Workbook

Sheet Seguimiento entrevistas
C1: Nota: El contacto deberá iniciarse con al menos 2 semanas de anticipación
C2: Leyenda: | E2: Actor que ya participó en algúna actividad
E3: Actor que será contactado por parte de APOYO
E4: Contacto brindado por otro actor
C5: # | D5: Nombre | E5: Institución | F5: Alcance (nivel nacional o distrito judicial) | G5: Actividad piloto | H5: ¿Asistió? | I5: Categoría | J5: Tipo | K5: Subtipo | L5: Actividad campo | M5: ¿Asistió? | N5: Contacto personal | O5: Contacto de institución (mesa de partes) | P5: Estrategia de acercamiento | Q5: Requiere Oficio | R5: Encargado | S5: ¿Envío de oficio? | T5: ¿Contactado? | U5: Estado | V5: Fecha de primer contacto | W5: Fecha de segundo contacto | X5: Fecha de tercer contacto | Y5: Fecha propuesta | Z5: Fecha de inicio de actividad | AA5: Fecha de fin de actividad | AB5: Modalidad | AC5: Duración total (min) | AD5: Comentarios /Observaciones IJM
B6: Nacional | C6: 1 | D6: Guadalupe Hinojosa Valencia | E6: Paz y esperanza | F6: Distrito Judicial: Cusco | G6: N/A | H6: N/A | I6: Multilaterales | J6: Fin principal relacionado con temas del estudio | K6: No aplica | L6: Entrevista de actores clave | N6: - Correo: aspazes@pazyesperanza.org - Tlf: +51 965789056 - Dirección: Jr. Pachacutec 980 Jesús María Lima 11, Perú | O6: No aplica | P6: - Enviar oficio formal - Confirmar recepción del oficio - Dar seguimiento telefónico | Q6: Sí | R6: IJM | T6: Sí | U6: Realizada completa | V6: 4/8/2026 | W6: 6/11/2026 | Y6: 6/15/2026 | AB6: A distancia asistido | AD6: Se encuentra en Italia, y estará revisando al agenda disponible por la diferencia de horas./ Definió la Agenda. | AE6: 1
B7: Nacional | C7: 2 | D7: Isabel López Meza | E7: Paz y esperanza | F7: Nacional | G7: N/A | H7: N/A | I7: Multilaterales | J7: Fin principal relacionado con temas del estudio | K7: No aplica | L7: Entrevista de actores clave | N7: - Correo: aspazes@pazyesperanza.org - Tlf: +51 965789056 - Dirección: Jr. Pachacutec 980 Jesús María Lima 11, Perú | O7: No aplica | P7: - Enviar oficio formal - Confirmar recepción del oficio - Dar seguimiento telefónico | Q7: Sí | R7: IJM | T7: No | U7: No válida | AD7: No será entrevistada. Será remplazada por Esley Nieto de Paz y Esperanza | AE7: 1
B8: Nacional | C8: 3 | D8: Víctor García | E8: Plan International | F8: Nacional | G8: N/A | H8: N/A | I8: Multilaterales | J8: Fin principal relacionado con temas del estudio | K8: No aplica | L8: Entrevista de actores clave | N8: - Dirección: Av. Juan de Arona, N° 755, Piso 9, San Isidro - Correo: informes.peru@plan-international.org | O8: No aplica | P8: - Enviar oficio formal - Confirmar recepción del oficio - Dar seguimiento telefónico | Q8: Sí | R8: IJM | S8: Sí | T8: Sí | U8: Sin respuesta | V8: 5/5/2026 | W8: 6/11/2026 | AD8: Reiterar mensaje | AE8: 1
B9: Nacional | C9: 4 | D9: Marlene Molero Suárez | E9: Care Perú | F9: Nacional | G9: N/A | H9: N/A | I9: Multilaterales | J9: Fin principal relacionado con temas del estudio | K9: No aplica | L9: Entrevista de actores clave | N9: - Tlf: +51 (01) 6409393 - Correo: central@care.org.pe/<marlene.molero@elsa.la> -Dirección: Calle Amador Merino Reyna 267, piso 9, oficina 901, San Isidro. Lima – Perú | O9: No aplica | P9: - Enviar oficio formal - Confirmar recepción del oficio - Dar seguimiento telefónico | Q9: Sí | R9: IJM | T9: No | V9: 3/19/2026 | AD9: Volver a llamar | AE9: 0
B10: Nacional | C10: 5 | D10: Marilú Martens Cortés | E10: Care Perú | F10: Nacional | G10: N/A | H10: N/A | I10: Multilaterales | J10: Fin principal relacionado con temas del estudio | K10: No aplica | L10: Entrevista de actores clave | N10: - Tlf: +51 (01) 6409393 - Correo: central@care.org.pe -Dirección: Calle Amador Merino Reyna 267, piso 9, oficina 901, San Isidro. Lima – Perú | O10: No aplica | P10: - Enviar oficio formal - Confirmar recepción del oficio - Dar seguimiento telefónico | Q10: Sí | R10: IJM | T10: Sí | U10: Sin respuesta | V10: 3/19/2026 | AD10: Volver a llamar | AE10: 1
B11: Nacional | C11: 6 | D11: Rafael Casas | E11: Aldeas Infantiles SOS | F11: Nacional | G11: N/A | H11: N/A | I11: Multilaterales | J11: Fin principal relacionado con temas del estudio | K11: No aplica | L11: Entrevista de actores clave | N11: - Tlf. +51 (01) 200-7800 - Dirección: Calle Ricardo Angulo 744. Urb. Córpac - San Isidro. -Correo: empresas.amigas@aldeasinfantiles.org.pe | O11: No aplica | P11: - Enviar oficio formal - Confirmar recepción del oficio - Dar seguimiento telefónico | Q11: Sí | R11: IJM | T11: Sí | U11: Realizada completa | V11: 3/19/2026 | W11: 3/23/2026 | Z11: 8-May | AB11: A distancia asistido | AE11: 1
B12: Nacional | C12: 7 | D12: Sonia Gleci Frisancho Pacheco | E12: Aldeas Infantiles SOS | F12: Nacional | G12: N/A | H12: N/A | I12: Multilaterales | J12: Fin principal relacionado con temas del estudio | K12: No aplica | L12: Entrevista de actores clave | N12: - Tlf. +51 (01) 200-7800 - Dirección: Calle Ricardo Angulo 744. Urb. Córpac - San Isidro. -Correo: empresas.amigas@aldeasinfantiles.org.pe | O12: No aplica | P12: - Enviar oficio formal - Confirmar recepción del oficio - Dar seguimiento telefónico | Q12: Sí | R12: IJM | T12: No | V12: 3/19/2026 | AD12: Volver a llamar | AE12: 0
B13: Nacional | C13: 8 | D13: Alejandra Saffon | E13: Organización para la Cooperación y el Desarrollo Económico | F13: Nacional | G13: N/A | H13: N/A | I13: Multilaterales | J13: Fin principal relacionado con temas del estudio | K13: No aplica | L13: Entrevista de actores clave | N13: https://www.linkedin.com/in/alejandra-saffon-26761671/?originalSubdomain=co/ 928974196 | O13: No aplica | P13: - Enviar oficio formal - Confirmar recepción del oficio | Q13: Sí | R13: IJM | T13: No | V13: 3/23/2026 | AD13: 928974196 Cel de inter no contestó | AE13: 0
B14: Nacional | C14: 9 | D14: Elena Portilla Odlianitskaya | E14: Organización para la Cooperación y el Desarrollo Económico | F14: Nacional | G14: N/A | H14: N/A | I14: Multilaterales | J14: Fin principal relacionado con temas del estudio | K14: No aplica | L14: Entrevista de actores clave | N14: https://www.linkedin.com/in/elena-portilla-odlianitskaya/ | O14: No aplica | P14: - Enviar oficio formal - Confirmar recepción del oficio | Q14: Sí | R14: IJM | T14: No | AE14: 0
B15: Nacional | C15: 10 | D15: Alejandra Alayza | E15: Oxfam | F15: Nacional | G15: N/A | H15: N/A | I15: Multilaterales | J15: Fin principal relacionado con temas del estudio | K15: No aplica | L15: Entrevista de actores clave | N15: alejandra.alayza@oxfam.org '+51 984753054 | O15: No aplica | P15: - Enviar oficio formal - Confirmar recepción del oficio | Q15: Sí | R15: IJM | T15: No | AE15: 0
B16: Nacional | C16: 11 | D16: Miguel Lévano | E16: Oxfam | F16: Nacional | G16: N/A | H16: N/A | I16: Multilaterales | J16: Fin principal relacionado con temas del estudio | K16: No aplica | L16: Entrevista de actores clave | N16: miguel.levano@oxfam.org | O16: No aplica | P16: - Enviar oficio formal - Confirmar recepción del oficio | Q16: Sí | R16: IJM | T16: No | AE16: 0
B17: Distrito Judicial: Ucayali | C17: 12 | D17: Esteban Caballero | E17: UNFPA | F17: Distrito Judicial: Ucayali | G17: N/A | H17: N/A | I17: Multilaterales | J17: Fin principal relacionado con temas del estudio | K17: No aplica | L17: Entrevista de actores clave | N17: caballero@unfpa.org.pe | O17: No aplica | P17: - Enviar oficio formal - Confirmar recepción del oficio - Dar seguimiento telefónico | Q17: Sí | R17: IJM | T17: No | V17: 3/23/2026 | AD17: No contesta y desde el fijo se corta. Enviar correo | AE17: 0
B18: Nacional | C18: 13 | D18: Hugo González Coltrinari | E18: UNFPA | F18: Nacional | G18: N/A | H18: N/A | I18: Multilaterales | J18: Fin principal relacionado con temas del estudio | K18: No aplica | L18: Entrevista de actores clave | N18: gonzalez@unfpa.org | O18: No aplica | P18: - Enviar oficio formal - Confirmar recepción del oficio - Dar seguimiento telefónico | Q18: Sí | R18: IJM | T18: No | AE18: 0
B19: Nacional | C19: 14 | D19: Tomás Lopes-Teixeira | E19: Banco Interamericano de Desarrollo | F19: Nacional | G19: N/A | H19: N/A | I19: Multilaterales | J19: Fin principal relacionado con temas del estudio | K19: No aplica | L19: Entrevista de actores clave | N19: (51-1) 215-7800 BIDPeru@iadb.orgv | O19: No aplica | P19: - Enviar oficio formal - Confirmar recepción del oficio - Dar seguimiento telefónico | Q19: Sí | R19: IJM | T19: No | V19: 3/23/2026 | AD19: Contesta la operadora. Enviar correo | AE19: 0
B20: Distrito Judicial: Apurímac | C20: 15 | D20: Issam Abousleiman | E20: World Bank | F20: Distrito Judicial: Apurímac | G20: N/A | H20: N/A | I20: Multilaterales | J20: Fin principal relacionado con temas del estudio | K20: No aplica | L20: Entrevista de actores clave | N20: +51 1 622-2300 | O20: No aplica | P20: - Convocar mediante llamada | Q20: No | R20: IJM | T20: No | AE20: 0
B21: Nacional | C21: 16 | D21: Carlos Jesús Vilela | E21: Jurado Nacional de Elecciones | F21: Distrito Judicial: Lima | G21: N/A | H21: N/A | I21: Funcionarios del Sistema | J21: Instituciones públicas | K21: MIMP | L21: Entrevista de actores clave | N21: +51 966662278 | O21: cvilela@jne.gob.pe | P21: - Enviar oficio formal - Confirmar recepción del oficio - Dar seguimiento telefónico a través del punto focal identificado -Confirmar participación | Q21: Sí | R21: IJM | T21: Sí | U21: Sin respuesta | V21: 3/20/2026 | W21: 4/10/2026 | AD21: Mensaje vía whatsApp. Contestó; se le mencionó hora y fecha, esperando respuesta. Se volvio a enviar mensaje el 08/05/26 | AE21: 1
B22: Distrito Judicial: Loreto | C22: 17 | D22: Mónica Mendez Cabezas | E22: Ministerio de la Mujer | F22: Distrito Judicial: Loreto | G22: N/A | H22: N/A | I22: Funcionarios del Sistema | J22: Instituciones públicas | K22: MIMP | L22: Entrevista de actores clave | N22: +(01) 626 1600 Anexo 7170 mmendez@mimp.gob.pe | O22: mesadepartesdigital@mimp.gob.pe. | P22: - Enviar oficio formal - Confirmar recepción del oficio - Dar seguimiento telefónico a través del punto focal identificado -Confirmar participación | Q22: Sí | R22: IJM | T22: Sí | U22: Sin respuesta | V22: 5/5/2026 | AE22: 1
B23: Distrito Judicial: Ayacucho | C23: 18 | D23: Kenny Jorge Perez Diaz | E23: Ministerio de la Mujer | F23: Distrito Judicial: Ayacucho | G23: N/A | H23: N/A | I23: Funcionarios del Sistema | J23: Instituciones públicas | K23: MIMP | L23: Entrevista de actores clave | N23: +51 (01) 6261600 kperez@mimp.gob.pe | O23: mesadepartesdigital@mimp.gob.pe. | P23: - Enviar oficio formal - Confirmar recepción del oficio - Dar seguimiento telefónico a través del punto focal identificado -Confirmar participación | Q23: Sí | R23: IJM | T23: Sí | U23: En coordinación | V23: 4/14/2026 | AD23: por 06 días en diferentes fechas se ha intentado coordinar pero no se concreta, dice que si y luego no responde. | AE23: 1
B24: Distrito Judicial: Ayacucho | C24: 19 | D24: Laura Esther Agama Fernández | E24: Ministerio de la Mujer | F24: Distrito Judicial: Ayacucho | G24: N/A | H24: N/A | I24: Funcionarios del Sistema | J24: Instituciones públicas | K24: MIMP | L24: Entrevista de actores clave | N24: 01- 4197260 / Anexo 3602 lagama@aurora.gob.pe | O24: mesadepartesdigital@mimp.gob.pe. | P24: - Enviar oficio formal - Confirmar recepción del oficio - Dar seguimiento telefónico a través del punto focal identificado -Confirmar participación | Q24: Sí | R24: IJM | S24: Sí | T24: Sí | U24: Sin respuesta | V24: 5/5/2026 | AE24: 1
B25: Distrito Judicial: Huánuco | C25: 20 | D25: Doris Godoy Cortez | E25: Psicólogos | F25: Distrito Judicial: Huánuco | G25: N/A | H25: N/A | I25: Acompañantes | J25: ONGs | K25: No aplica | L25: Entrevista de actores clave | N25: +51 962960076 dgodoy@pazyesperanza.org | O25: No aplica | P25: - Enviar correos con convocatoria - Dar seguimiento telefónico | Q25: No | R25: IJM | T25: Sí | U25: Realizada completa | V25: 3/20/2026 | Z25: 31-Mar | AA25: 31-Mar | AB25: A distancia asistido | AC25: 60 | AD25: Mensaje vía whatsapp. Aceptó entrevista | AE25: 1
B26: Nacional | C26: 21 | D26: Rosa Peña | E26: Kids Alive | F26: Nacional | G26: N/A | H26: N/A | I26: Actores locales | J26: ONGs | K26: Foco en derechos de la niñez | L26: Entrevista de actores clave | N26: +51 914777004 | O26: No aplica | P26: - Convocar mediante llamada | Q26: No | R26: IJM | T26: Sí | U26: Realizada completa | V26: 3/23/2026 | Y26: 3/24/2026 | Z26: 24-Mar | AA26: 24-Mar | AB26: A distancia asistido | AC26: 42 | AD26: Aceptó entrevista. | AE26: 1
B27: Nacional | C27: 22 | D27: Angie Vargas | E27: ONG: Movimiento Manuela Ramos | F27: Distrito Judicial: Lima Este | G27: Entrevista de actores clave | H27: No | I27: Actores locales | J27: ONGs | K27: Foco en derechos sexuales / reproductivos | L27: Entrevista de actores clave | N27: 968 072 723 linkedin.com/in/angie-rosmery-vargas-sacsahuillca-782694225 postmast@manuela.org.pe | O27: No aplica | P27: - Enviar correos con convocatoria - Dar seguimiento telefónico | Q27: No | R27: IJM | T27: Sí | U27: En coordinación | V27: 3/23/2026 | W27: 3/24/2026 | AD27: Me piden enviar invitación formal a nombre de Rocio Gutierrez directora | AE27: 1
B28: Distrito Judicial: Apurímac | C28: 23 | D28: Jharith Mogollón Villafuerte | E28: Asociación Pro Derechos Humanos (APRODEH) | F28: Distrito Judicial: Apurímac | G28: N/A | H28: N/A | I28: Acompañantes | J28: ONGs | K28: No aplica | L28: Entrevista de actores clave | N28: - Tlf. (01) 424-7057, 431-0482 - Dirección: Jr. Pachacútec 980 – Jesús María - Correo:postmast@aprodeh.org.pe | O28: No aplica | P28: - Enviar correos con convocatoria - Dar seguimiento telefónico | Q28: Sí | R28: IJM | T28: Sí | U28: Sin respuesta | V28: 3/23/2026 | W28: 5/5/2026 | AD28: se envio oficio por mesa de partes digital | AE28: 1
B29: Nacional | C29: 24 | D29: Rossina Guerrero | E29: Promoción y Defensa de los Derechos Sexuales y Reproductivos (PROMSEX) | F29: Nacional | G29: N/A | H29: N/A | I29: Actores locales | J29: ONGs | K29: Foco en derechos sexuales / reproductivos | L29: Entrevista de actores clave | N29: - Tlf: +51 (01) 4478668 - Dirección: Av. José Pardo 601 Oficina 604, Miraflores, Case Miraflores, Peru postmast@promdsr.org | O29: No aplica | P29: - Enviar correos con convocatoria - Dar seguimiento telefónico | Q29: No | R29: IJM | T29: Sí | U29: Sin respuesta | V29: 3/23/2026 | AD29: Enviar oficio; el teléfono fijo se corta. | AE29: 1
B30: Distrito Judicial: Lima Norte | C30: 25 | D30: Augusto Altamirano Vega | E30: Centros de Acogida Residencial | F30: Distrito Judicial: Lima Norte | G30: N/A | H30: N/A | I30: Funcionarios del Sistema | J30: Instituciones públicas | K30: Centros de Acogida Residencial | L30: Entrevista de actores clave | N30: asco | O30: No aplica | P30: - Enviar correos con convocatoria - Dar seguimiento telefónico | Q30: Sí | R30: IJM | S30: Sí | T30: Sí | U30: Rechazada | V30: 3/23/2026 | W30: 5/5/2026 | X30: 5/22/2026 | AD30: Se le envio nuevamente la carta por whatsapp porque el correo reboto | AE30: 1
B31: Nacional | C31: 26 | D31: María Luci Malpartida Galán | E31: Centros de Acogida Residencial | F31: Distrito Judicial: Lima | G31: N/A | H31: N/A | I31: Funcionarios del Sistema | J31: Instituciones públicas | K31: Centros de Acogida Residencial | L31: Entrevista de actores clave | N31: car.barcoiris@gmail.com cel 949605237 | O31: No aplica | P31: - Enviar correos con convocatoria - Dar seguimiento telefónico | Q31: Sí | R31: IJM | S31: Sí | T31: Sí | U31: Sin respuesta | V31: 5/5/2026 | AE31: 1
B32: Distrito Judicial: Ayacucho | C32: 27 | D32: Rosa Viviana Ciriaco Marcatinco | E32: Centros de Acogida Residencial | F32: Distrito Judicial: Ayacucho | G32: N/A | H32: N/A | I32: Funcionarios del Sistema | J32: Instituciones públicas | K32: Centros de Acogida Residencial | L32: Entrevista de actores clave | N32: care.dia@inabif.gob.pe | O32: No aplica | P32: - Enviar correos con convocatoria - Dar seguimiento telefónico | Q32: Sí | R32: IJM | S32: Sí | T32: Sí | U32: Realizada completa | V32: 5/5/2026 | Z32: 25-May | AB32: A distancia asistido | AE32: 1
B33: Distrito Judicial: Huánuco | C33: 28 | D33: Karen De Los Milagros Ucañan Cachy | E33: Centros de Acogida Residencial | F33: Distrito Judicial: Huánuco | G33: Entrevista de actores clave | H33: No | I33: Funcionarios del Sistema | J33: Instituciones públicas | K33: Centros de Acogida Residencial | L33: Entrevista de actores clave | N33: karen.uc7@hotmail.com | O33: No aplica | P33: - Enviar correos con convocatoria - Dar seguimiento telefónico | Q33: Sí | R33: IJM | S33: Sí | T33: Sí | U33: Sin respuesta | V33: 5/5/2026 | AE33: 1
B34: Nacional | C34: 29 | D34: Israel Mendez Miguel | E34: Centros de Acogida Residencial | F34: Distrito Judicial: Cusco | G34: N/A | H34: N/A | I34: Funcionarios del Sistema | J34: Instituciones públicas | K34: Centros de Acogida Residencial | L34: Entrevista de actores clave | N34: israel_8699@hotmail.com israelmemi4@gmail.com | O34: No aplica | P34: - Enviar correos con convocatoria - Dar seguimiento telefónico | Q34: Sí | R34: IJM | T34: Sí | U34: Rechazada | V34: 5/5/2026 | AD34: El distrito judicial es Ayacucho y reboto el correo | AE34: 1
B35: Nacional | C35: 30 | D35: María Barbara Venemans De Wilde | E35: Centros de Acogida Residencial | F35: Distrito Judicial: Lima | G35: Entrevista de actores clave | H35: No | I35: Funcionarios del Sistema | J35: Instituciones públicas | K35: Centros de Acogida Residencial | L35: Entrevista de actores clave | N35: alanyasantacruz@loscachorros.nl | O35: No aplica | P35: - Enviar correos con convocatoria - Dar seguimiento telefónico | Q35: Sí | R35: IJM | T35: Sí | U35: Sin respuesta | V35: 5/5/2026 | AD35: El distrito judicial es Ayacucho | AE35: 1
B36: Nacional | C36: 31 | D36: Martha Fernandez Albornett | E36: Asociación Protección Población Vulnerable | F36: Nacional | G36: N/A | H36: N/A | I36: Actores locales | J36: ONGs | K36: Foco en derechos de la niñez | L36: Entrevista de actores clave | N36: info@appv.pe | O36: No aplica | P36: - Enviar correos con convocatoria - Dar seguimiento telefónico | Q36: Sí | R36: IJM | S36: Sí | T36: Sí | U36: Sin respuesta | V36: 5/5/2026 | AE36: 1
B37: Nacional | C37: 32 | D37: Rocío Roncal Rojas | E37: Asociación Kallpa | F37: Nacional | G37: N/A | H37: N/A | I37: Actores locales | J37: ONGs | K37: Foco en derechos de la niñez | L37: Entrevista de actores clave | N37: 51-996-55-083 comunicaciones@kallpa.org.pe | O37: No aplica | P37: - Enviar correos con convocatoria - Dar seguimiento telefónico | Q37: Sí | R37: IJM | S37: Sí | T37: Sí | U37: Sin respuesta | V37: 5/5/2026 | W37: 5/20/2026 | AD37: se envío correo de seguimiento | AE37: 1
B38: Distrito Judicial: Apurímac | C38: 33 | D38: Pascual Benjamín Rivera Montoya | E38: Centro de Protección del Menor | F38: Distrito Judicial: Apurímac | G38: N/A | H38: N/A | I38: Acompañantes | J38: ONGs | K38: No aplica | L38: Entrevista de actores clave | N38: cenann.cep@iglesiacatolica.org.pe | O38: No aplica | P38: - Enviar correos con convocatoria | Q38: Sí | R38: IJM | S38: Sí | T38: Sí | U38: Sin respuesta | V38: 5/5/2026 | AD38: correo reboto | AE38: 1
B39: Nacional | C39: 34 | D39: Coronel Ernesto Peña | E39: Jueces de Paz | F39: Nacional | G39: N/A | H39: N/A | I39: Funcionarios del Sistema | J39: Instituciones públicas | K39: Jueces de paz | L39: Entrevista de actores clave | N39: 987856989 | O39: No aplica | P39: - Convocar mediante llamada | Q39: Sí | R39: IJM | S39: Sí | T39: Sí | U39: Sin respuesta | V39: 3/23/2026 | W39: 5/5/2026 | AD39: Mensaje vía whatsapp. | AE39: 1
B40: Distrito Judicial: Cajamarca | C40: 35 | D40: Fátima Joyo Zaga | E40: Jueces de Paz | F40: Distrito Judicial: Cajamarca | G40: N/A | H40: N/A | I40: Funcionarios del Sistema | J40: Instituciones públicas | K40: Jueces de paz | L40: Entrevista de actores clave | N40: rjoyo@pj.gob.pe | O40: No aplica | P40: - Enviar oficio formal - Confirmar recepción del oficio - Dar seguimiento telefónico | Q40: Sí | R40: IJM | S40: Sí | T40: Sí | U40: Rechazada | V40: 5/5/2026 | AD40: Reboto el correo | AE40: 1
...

Sheet Seguimiento grupos focales
C1: Nota: El contacto deberá iniciarse con al menos 2 semanas de anticipación
C2: Leyenda: | E2: Actor que ya participó en algúna actividad
E3: Actor que será contactado por parte de APOYO
E4: Contacto brindado por otro actor
E5: Por evaluar
C6: # | D6: Nombre | E6: Institución | F6: Alcance (nivel nacional o distrito judicial) | G6: Actividad piloto | H6: ¿Asistió? | I6: Tipo de actor | J6: Actividad campo | K6: N° de Grupo Focal | L6: ¿Asistió? | M6: Contacto personal | N6: Contacto de institución (mesa de partes) | O6: Estrategia de acercamiento | P6: Requiere Oficio | Q6: Encargado | R6: ¿Envío de oficio? | S6: ¿Contactado? | T6: Respuesta | U6: Fecha de primer contacto | V6: Fecha de segundo contacto | W6: Fecha de tercer contacto | X6: Fecha propuesta | Y6: Fecha de inicio de actividad | Z6: Fecha de fin de actividad | AA6: Modalidad | AB6: Resultado | AC6: Duración total (min) | AD6: Comentarios /Observaciones IJM
C7: 1 | D7: Sofía Blamey Andrusco | E7: Organización para la Cooperación y el Desarrollo Económico | F7: Nacional | G7: N/A | H7: N/A | I7: Multilaterales | J7: Grupo focal de reconocimiento | K7: Grupo focal 1 | M7: https://www.linkedin.com/in/sofia-blamey-andrusco-7520096b/?locale=fr_FR | N7: No aplica | O7: - Enviar oficio formal - Confirmar recepción del oficio | P7: Sí | Q7: IJM | R7: Sí | S7: Sí | T7: Sin respuesta | U7: 4/27/2026 | V7: 6-May | AD7: Correo ubicado en web rebotó
C8: 2 | D8: Cinthia Navarro | E8: Oxfam | F8: Nacional | G8: Reunión de reconocimiento | H8: No | I8: Multilaterales | J8: Grupo focal de reconocimiento | K8: Grupo focal 2 | M8: cinthia.navarro@oxfam.org cinavarro@pucp.pe | N8: No aplica | O8: - Enviar oficio formal - Confirmar recepción del oficio | P8: Sí | Q8: IJM | R8: Sí | S8: Sí | T8: Sin respuesta | U8: 4/27/2026 | V8: 6-May | W8: 15-May | AD8: Correo insitucional rebotó
C9: 3 | D9: Sofia Garcia | E9: Instituto Promoviendo Desarrollo Social-IPRODES | F9: Distrito Judicial: Huánuco | G9: Reunión de reconocimiento | H9: No | I9: Multilaterales | J9: Grupo focal de reconocimiento | K9: Grupo focal 2 | L9: Sí | M9: +51 992917139 | N9: No aplica | O9: - Convocar mediante llamada | P9: No | Q9: APOYO | R9: Sí | S9: Sí | T9: Aceptada | U9: 29-Apr | V9: 8-May | W9: 14-May | X9: 20-May | AB9: Completa | AD9: Se envió enlace y consentimiento por whatsapp.
C10: 4 | D10: Sandra Contreras | E10: World Vision | F10: Nacional | G10: Reunión de validación | H10: No | I10: Multilaterales | J10: Grupo focal de reconocimiento | K10: Grupo focal 2 | M10: (01) 513-6500 | N10: No aplica | O10: - Convocar mediante llamada | P10: No | Q10: APOYO | S10: Sí | T10: Sin respuesta | U10: 9-Apr | V10: 6-May | AD10: No responden al número.
C11: 5 | D11: Silvia Romero Borda | E11: GIZ | F11: Nacional | G11: Reunión de validación | H11: No | I11: Multilaterales | J11: Grupo focal de reconocimiento | K11: Grupo focal 1 | L11: No | M11: silvia.romeroborda@giz.de giz-peru@giz.de +51 1 4229067 | N11: No aplica | O11: - Enviar oficio formal - Confirmar recepción del oficio - Dar seguimiento telefónico | P11: Sí | Q11: IJM | R11: Sí | S11: Sí | T11: Aceptada | U11: 4/27/2026 | V11: 12-May | W11: 14-May | X11: 11-May | AD11: Aceptó para el 11, pero no se conectó.
C12: 6 | D12: Sandy Martinez | E12: GIZ | L12: Sí | M12: sandy.martinez@giz.de 986742519 | T12: Aceptada | X12: 20-May | AB12: Completa | AD12: Se envió enlace y consentimiento por correo. Designada de Silvia Romero. Asesora técnica del proyecto ForSNEJ II
C13: 7 | D13: Lissette Tobar | E13: Fundación Arbol de la Vida | F13: Distrito Judicial: Ucayali | G13: N/A | H13: N/A | I13: Multilaterales | J13: Grupo focal de reconocimiento | K13: Grupo focal 2 | M13: +51 (01) 2512724 peru.fondazione@alberodellavita.org | N13: No aplica | O13: - Enviar oficio formal - Confirmar recepción del oficio - Dar seguimiento telefónico | P13: Sí | Q13: IJM | R13: Sí | S13: Sí | T13: Sin respuesta | U13: 4/27/2026 | V13: 6-May | W13: 15-May | AD13: Correo reenviado
C14: 8 | D14: Jenny Dador | E14: Coordinadora de Derechos Humanos | F14: Distrito Judicial: Lima Este | G14: Reunión de reconocimiento | H14: No | I14: Multilaterales | J14: Grupo focal de reconocimiento | K14: Grupo focal 1 | M14: 953297789 | N14: No aplica | O14: - Convocar mediante llamada | P14: No | Q14: APOYO | R14: Sí | S14: Sí | T14: Sin respuesta | U14: 29-Apr | V14: 6-May | W14: 14-May | AD14: Para piloto se le contactó por WhatsApp y no respondió. 6/5: Se insisitó contacto, sin respuesta.
C15: 9 | D15: Oscar Andrés Alva Arías | E15: Ministerio de la Mujer | F15: Nacional | G15: Reunión de reconocimiento | H15: No | I15: Actores locales | J15: Grupo focal de reconocimiento | K15: Grupo focal 2 | L15: Sí | M15: +51 981164882 oalva@mimp.gob.pe | N15: mesadepartesdigital@mimp.gob.pe. | O15: - Enviar oficio formal - Confirmar recepción del oficio - Dar seguimiento telefónico a través del punto focal identificado -Confirmar participación | P15: Sí | Q15: IJM | R15: Sí | S15: Sí | T15: Aceptada | U15: 4/27/2026 | X15: 20-May | AB15: Completa | AD15: Se envió enlace y consentimiento por correo.
C16: 10 | D16: Gloria Cano | E16: Asociación Pro Derechos Humanos (APRODEH) | F16: Nacional | G16: N/A | H16: N/A | I16: Actores locales | J16: Grupo focal de reconocimiento | K16: Grupo focal 1 | M16: - Tlf. (01) 424-7057, 431-0482 - Dirección: Jr. Pachacútec 980 – Jesús María - Correo: postmast@aprodeh.org.pe, gloria@aprodeh.org.pe | N16: No aplica | O16: - Enviar correos con convocatoria - Dar seguimiento telefónico | P16: No | Q16: APOYO | R16: Sí | S16: Sí | T16: Sin respuesta | U16: 29-Apr | V16: 6-May | AD16: Solo correo
C17: 11 | D17: Maria Elena Bazan Ponce de Leon | E17: Centros de Acogida Residencial | F17: Distrito Judicial: Lima Norte | G17: Reunión de validación | H17: No | I17: Actores locales | J17: Grupo focal de reconocimiento | K17: Grupo focal 2 | M17: Tlf: 381-7190, 940228242 | N17: car.gracia@inabif.gob.pe | O17: - Convocar mediante llamada | P17: No | Q17: APOYO | R17: Sí | S17: Sí | T17: Sin respuesta | U17: 29-Apr | V17: 6-May | W17: 8-May | AD17: -
C18: 12 | D18: Sara Estela Rivera Almerco | E18: Centros de Acogida Residencial | F18: Distrito Judicial: Huánuco | G18: N/A | H18: N/A | I18: Actores locales | J18: Grupo focal de reconocimiento | K18: Grupo focal 1 | M18: aisanjuanb@gmail.com | N18: 940 314 251 / 942 261 067 (Directora) / 062-561275 sanjuanboscoaldeainfantil@gmail.com | O18: - Enviar correos con convocatoria - Dar seguimiento telefónico | P18: No | Q18: APOYO | R18: Sí | S18: Sí | T18: Sin respuesta | U18: 29-Apr | V18: 6-May | W18: 8-May | AD18: -
C19: 13 | D19: Soledad Chavez Bedoya | E19: Centros de Acogida Residencial | F19: Distrito Judicial: Lima | G19: N/A | H19: N/A | I19: Actores locales | J19: Grupo focal de reconocimiento | K19: Grupo focal 2 | M19: (01) 352-1199 | N19: 01-232-1451 (anexo 17) o 960 812 545 sociedaddebeneficenciahuacho@gmail.com | O19: - Convocar mediante llamada | P19: No | Q19: APOYO | S19: No | T19: Sin respuesta | U19: 8-May | V19: 12-May | W19: 15-May | AD19: -
C20: 14 | D20: Silvia Arteaga | E20: Centros de Acogida Residencial | F20: Distrito Judicial: Lima Este | G20: Reunión de reconocimiento | H20: No | I20: Actores locales | J20: Grupo focal de reconocimiento | K20: Grupo focal 2 | M20: car.sricardo@inabif.gob.pe | N20: 980654143 / 940244602 | O20: - Enviar correos con convocatoria - Dar seguimiento telefónico | P20: No | Q20: APOYO | R20: Sí | S20: Sí | T20: Aceptada | U20: 29-Apr | V20: 6-May | W20: 8-May | X20: 20-May | AD20: Se envió enlace y consentimiento por whatsapp. Solicitó cambio de fecha: del 11 al 20.
C21: 15 | D21: Karolina | E21: Centros de Acogida Residencial | F21: Distrito Judicial: Lima Este | G21: Reunión de reconocimiento | H21: No | I21: Actores locales | J21: Grupo focal de reconocimiento | K21: Grupo focal 2 | M21: car.sricardo@inabif.gob.pe | N21: 933 985 424 | O21: - Enviar correos con convocatoria - Dar seguimiento telefónico | P21: No | Q21: APOYO | R21: Sí | S21: Sí | T21: Aceptada | U21: 11-May | X21: 20-May | AD21: Se envió enlace y consentimiento por whatsapp. Psicóloga del CAR, referida por Silvia.
C22: 16 | D22: Carol Tremont | E22: Asociación Protección Población Vulnerable | F22: Distrito Judicial: Lima | G22: Reunión de reconocimiento | H22: No | I22: Actores locales | J22: Grupo focal de reconocimiento | K22: Grupo focal 2 | M22: info@appv.pe | N22: No aplica | O22: - Enviar correos con convocatoria - Dar seguimiento telefónico | P22: No | Q22: APOYO | R22: Sí | S22: Sí | T22: Sin respuesta | U22: 29-Apr | V22: 6-May | AD22: Solo correo
C23: 17 | D23: Intikilla Eutropía Delgado Castro | E23: Asociación Kallpa | F23: Distrito Judicial: Ayacucho | G23: Entrevista de actores clave | H23: No | I23: Actores locales | J23: Grupo focal de reconocimiento | K23: Grupo focal 1 | M23: https://www.linkedin.com/in/intikilla-eutrop%C3%ADa-delgado-castro-9a585934/ | N23: 51-996-55-83 comunicaciones@kallpa.org.pe, peru@kallpa.org.pe | O23: - Enviar correos con convocatoria - Dar seguimiento telefónico | P23: No | Q23: APOYO | R23: Sí | S23: Sí | T23: Sin respuesta | U23: 29-Apr | V23: 6-May | W23: 8-May | AD23: No responden número ni correo (desde el piloto).
C24: 18 | D24: Rosario Cosar | E24: Asociación Kallpa | F24: Nacional | G24: Reunión de reconocimiento | H24: No | I24: Actores locales | J24: Grupo focal de reconocimiento | K24: Grupo focal 2 | M24: https://www.linkedin.com/in/rosario-cosar-5b3538119/ 51-996-055-083 comunicaciones@kallpa.org.pe, peru@kallpa.org.pe | O24: - Enviar correos con convocatoria - Dar seguimiento telefónico | P24: No | Q24: APOYO | R24: Sí | S24: Sí | T24: Sin respuesta | U24: 29-Apr | V24: 6-May | W24: 8-May | AD24: No responden número ni correo (desde el piloto).
C25: 19 | D25: Lourdes Febres | E25: Acción por los niños | F25: Distrito Judicial: Cajamarca | G25: Reunión de validación | H25: No | I25: Actores locales | J25: Grupo focal de reconocimiento | K25: Grupo focal 2 | L25: Sí | M25: lourdes.febres@accionporlosninos.org.pe 995579501 | N25: No aplica | O25: - Enviar correos con convocatoria | P25: No | Q25: APOYO | R25: Sí | S25: Sí | T25: Aceptada | U25: 29-Apr | V25: 6-May | X25: 20-May | AB25: Completa | AD25: Se envió enlace y consentimiento por correo.
C26: 20 | D26: Magaly Blas | E26: Colegio Médico del Perú | F26: Distrito Judicial: Lima Norte | G26: Reunión de reconocimiento | H26: No | I26: Actores locales | J26: Grupo focal de reconocimiento | K26: Grupo focal 2 | M26: magaly.blas.b@upch.pe | N26: No aplica | O26: - Enviar correos con convocatoria - Dar seguimiento telefónico | P26: No | Q26: APOYO | R26: Sí | S26: Sí | T26: Sin respuesta | U26: 29-Apr | V26: 6-May | AD26: Solo correo
C27: 21 | D27: Gabriela Osco Chuquizuta | E27: Red Interquorum | F27: Nacional | G27: N/A | H27: N/A | I27: Actores locales | J27: Grupo focal de reconocimiento | K27: Grupo focal 1 | M27: redinterquorum@gmail.com | N27: (01) 4418494 | O27: - Enviar correos con convocatoria - Dar seguimiento telefónico | P27: No | Q27: APOYO | R27: Sí | S27: Sí | T27: Sin respuesta | U27: 29-Apr | V27: 6-May | AD27: Solo correo
C28: 22 | D28: Inés Agresott | E28: Mujeres Migrantes Maltratadas | F28: Nacional | G28: N/A | H28: N/A | I28: Actores locales | J28: Grupo focal de reconocimiento | K28: Grupo focal 2 | M28: madresmigrantesextranjerasperu@gmail.com | N28: No aplica | O28: - Enviar correos con convocatoria - Dar seguimiento telefónico | P28: No | Q28: APOYO | R28: Sí | S28: Sí | T28: Sin respuesta | U28: 29-Apr | V28: 6-May | AD28: Solo correo
C29: 23 | D29: Arlette Contreras | E29: Ni una menos | F29: Distrito Judicial: Cusco | G29: Reunión de reconocimiento | H29: No | I29: Actores locales | J29: Grupo focal de reconocimiento | K29: Grupo focal 1 | M29: arlettecontreras@agendamujer.com | N29: No aplica | O29: - Enviar correos con convocatoria - Dar seguimiento telefónico | P29: No | Q29: APOYO | R29: Sí | S29: Sí | T29: Sin respuesta | U29: 29-Apr | V29: 6-May | AD29: Solo correo
C30: 24 | D30: Sandy Evangelista | E30: Familias Unidas Por Justicia: Familiares de Víctimas de Feminicidio | F30: Distrito Judicial: Amazonas | G30: N/A | H30: N/A | I30: Actores locales | J30: Grupo focal de reconocimiento | K30: Grupo focal 2 | L30: Sí | M30: familiasunidasporjusticia@gmail.com | N30: No aplica | O30: - Enviar correos con convocatoria - Dar seguimiento telefónico | P30: No | Q30: APOYO | R30: Sí | S30: Sí | T30: Aceptada | U30: 29-Apr | X30: 20-May | AB30: Completa | AD30: Paola Ricci (Comunicaciones) responidó al correo señalando que la Presidenta es Katherine Flores. Ella ya participó del GF piloto.
C31: 25 | D31: Victoria Pomalaya Trillo | E31: Ministerio Público (Fiscalía) | F31: Distrito Judicial: Ayacucho | G31: Reunión de validación | H31: No | I31: Funcionarios del Sistema | J31: Grupo focal de reconocimiento | K31: Grupo focal 1 | L31: Sí | M31: 945 023 096, 061579750 anexo 3019 vpomalaya@mpfn.gob.pe; victoriapomalaya@gmail.com | N31: mesa_de_partes_gg@mpfn.gob.pe mesadepartes1FSuprP@mpfn.gob.pe | O31: - Enviar oficio formal - Confirmar recepción del oficio - Definir punto focal - Dar seguimiento telefónico | P31: Sí | Q31: IJM | R31: Sí | S31: Sí | T31: Aceptada | U31: 4/27/2026 | V31: 6-May | X31: 11-May | AB31: Completa | AD31: Se envió enlace y consentimiento a correo y/o whatsapp.
C32: 26 | D32: Ulises Requejo | E32: Ministerio Público (Fiscalía) | F32: Distrito Judicial: Ayacucho | G32: N/A | H32: N/A | I32: Funcionarios del Sistema | J32: Grupo focal de reconocimiento | K32: Grupo focal 2 | M32: 997 918 714 | S32: Sí | T32: Aceptada | U32: 5/7/2026 | V32: 8-May | X32: 20-May | AD32: Se envió enlace y consentimiento por Whatsapp. Contacto brindado por Victoria Pomalaya Trillo. Ulises es fiscal de Violencia contra la Mujer y Grupo Familiar.
C33: 27 | D33: Norma Rojas | E33: Ministerio del Interior | F33: Distrito Judicial: Apurímac | G33: Reunión de validación | H33: No | I33: Funcionarios del Sistema | J33: Grupo focal de reconocimiento | K33: Grupo focal 2 | M33: 993819250 | N33: https://sistemas.mininter.gob.pe/mesadepartesdigital/ | O33: - Enviar oficio formal - Confirmar recepción del oficio - Definir punto focal - Dar seguimiento telefónico | P33: Sí | Q33: IJM | R33: Sí | S33: Sí | T33: Rechazada | U33: 4/27/2026 | AD33: Aceptó para el 20 érp camceñp ór salud
C34: 28 | D34: Angel Grimaldo Palacios Trujillo | E34: Centros de Emergencia Mujer | F34: Distrito Judicial: Ucayali | G34: Reunión de reconocimiento | H34: No | I34: Acompañantes | J34: Grupo focal de reconocimiento | K34: Grupo focal 1 | M34: Tlf: 542-0552 asistenciaeconomica@waminam.gob.pe | N34: No aplica | O34: - Enviar oficio formal - Confirmar recepción del oficio - Dar seguimiento telefónico | P34: Sí | Q34: IJM | R34: Sí | S34: Sí | T34: Sin respuesta | U34: 4/27/2026 | V34: 6-May | AD34: Correo reenviado
C35: 29 | D35: Heydy Taype Pérez | E35: Centros de Emergencia Mujer | F35: Distrito Judicial: Huánuco | G35: N/A | H35: N/A | I35: Acompañantes | J35: Grupo focal de reconocimiento | K35: Grupo focal 2 | M35: +51 994833661 | N35: No aplica | O35: - Enviar oficio formal - Confirmar recepción del oficio - Dar seguimiento telefónico | P35: Sí | Q35: IJM | S35: No | T35: Sin respuesta | U35: 6-May | V35: 8-May | AD35: No responde
C36: 30 | D36: Alicia Soledad Cusquisibán Sánchez | E36: Centros de Emergencia Mujer | F36: Distrito Judicial: Cajamarca | G36: N/A | H36: N/A | I36: Acompañantes | J36: Grupo focal de reconocimiento | K36: Grupo focal 1 | M36: Tlf. (066) 364000 '+51 994834045 | N36: No aplica | O36: - Enviar oficio formal - Confirmar recepción del oficio - Dar seguimiento telefónico | P36: Sí | Q36: IJM | S36: No | T36: Sin respuesta | U36: 6-May | V36: 8-May | AD36: No responde
C37: 31 | D37: Blanca Marianela Benites Avalos | E37: Centros de Emergencia Mujer | F37: Distrito Judicial: Cajamarca | G37: N/A | H37: N/A | I37: Acompañantes | J37: Grupo focal de reconocimiento | K37: Grupo focal 2 | M37: +51 994800484 | N37: No aplica | O37: - Enviar oficio formal - Confirmar recepción del oficio - Dar seguimiento telefónico | P37: Sí | Q37: IJM | S37: Sí | T37: Sin respuesta | U37: 6-May | AD37: 6/5: Blanca no es responsable del CEM hace dos años.
C38: 32 | D38: Jose Miguel Chavez Montero | E38: Centros de Emergencia Mujer | F38: Distrito Judicial: Ucayali | G38: N/A | H38: N/A | I38: Acompañantes | J38: Grupo focal de reconocimiento | N38: 994800484, cemucayaliloreto@gmail.com | S38: Sí | T38: En coordinación | U38: 6-May | V38: 8-May | AD38: Contactado a partir de la llamada a Blanca Marianela Benites Avalos.
C39: 33 | D39: Hellen Victoria Ku Yanasupo | E39: Centros de Emergencia Mujer | F39: Distrito Judicial: Lima | G39: N/A | H39: N/A | I39: Acompañantes | J39: Grupo focal de reconocimiento | K39: Grupo focal 1 | M39: hellen.ku@aurora.gob.pe | N39: No aplica | O39: - Enviar oficio formal - Confirmar recepción del oficio - Dar seguimiento telefónico | P39: Sí | Q39: IJM | R39: Sí | S39: Sí | T39: Sin respuesta | U39: 4/27/2026 | V39: 6-May | AD39: Correo reenviado
C40: 34 | D40: Zoila Cabanillas | E40: Wami Ñan | F40: Distrito Judicial: Lima | G40: Reunión de reconocimiento | H40: No | I40: Acompañantes | J40: Grupo focal de reconocimiento | K40: Grupo focal 2 | L40: Sí | M40: zoila.cabanillas@warminam.gob.pe 994581446 | N40: No aplica | O40: - Enviar oficio formal - Confirmar recepción del oficio - Dar seguimiento telefónico a través del punto focal identificado -Confirmar participación | P40: Sí | Q40: IJM | R40: Sí | S40: Sí | T40: Aceptada | U40: 4/27/2026 | V40: 6-May | X40: 20-May | AB40: Completa | AD40: Se envió enlace y consentimiento por correo. Asistirá con Vanessa Díaz (ella asistió al GF presencial).
...

Sheet Sobrevivientes
C1: # | D1: Nombre orientadora judicial | E1: Distrito Judicial | F1: Nombre de sobreviviente | G1: Contacto personal | H1: Encargado | I1: ¿Contactada? | J1: Respuesta | K1: Fecha de primer contacto | L1: Fecha de segundo contacto | M1: Fecha de tercer contacto | N1: Fecha propuesta | O1: Fecha de inicio de actividad | P1: Fecha de fin de actividad | Q1: Modalidad | R1: Resultado | S1: Duración total (min)
B2: Nacional | C2: 1 | D2: Leyden María Capa Barrios | E2: Distrito Judicial: Callao | F2: Zenobia (Señorita) | G2: 988 962 782 | I2: No | J2: En coordinación
B3: Nacional | C3: 2 | D3: Leyden María Capa Barrios | E3: Distrito Judicial: Callao | F3: CRISTINA MENDOZA (Lideresa) | G3: 980 934 848 | I3: No | J3: En coordinación
B4: Nacional | C4: 3 | D4: Leyden María Capa Barrios | E4: Distrito Judicial: Callao | F4: Naidolith Peña (Líder) | G4: 944 448 603 | I4: No | J4: En coordinación
B5: Nacional | C5: 4 | D5: Leyden María Capa Barrios | E5: Distrito Judicial: Callao | F5: Martha Quispe | G5: 931455311 | I5: No | J5: En coordinación
C6: 5 | D6: Líder | E6: Distrito Judicial: Huánuco | H6: APOYO | I6: Sí | J6: Realizada completa | Q6: Presencial | R6: Realizada completa
C7: 6 | D7: Sobreviviente01 | E7: Distrito Judicial: Huánuco | H7: APOYO | I7: Sí | J7: Realizada completa | Q7: Presencial | R7: Realizada completa
C8: 7 | D8: Sobreviviente02 | E8: Distrito Judicial: Huánuco | H8: APOYO | I8: Sí | J8: Realizada completa | Q8: Virtual | R8: Realizada completa

Sheet Entrevistas
A1: Identificador | B1: Nombre | C1: Institución | D1: Correo | E1: Número | F1: Otro contacto | G1: Tipo de entrevistas | H1: Tipo de actor | I1: Distrito judicial | J1: Encargado de contacto | K1: Contacto | L1: Fecha de primer contacto | M1: Fecha de segundo contacto | N1: Fecha de tercer contacto | O1: Respuesta del actor | P1: Fecha de inicio de entrevista | Q1: Fecha de fin de entrevista | R1: Resultado | S1: Duración total (min) | T1: Actor considerado inicialmente | U1: Modalidad establecida | V1: Modalidad aplicada | Y1: Observaciones (22102025) | Z1: Observaciones AC
A2: 1 | B2: Edgar Alfredo Rebaza Vargas | C2: Ministerio Público | D2: arebaza@mpfn.gob.pe | G2: Actores clave | H2: Funcionarios | I2: Cajamarca | J2: APOYO | K2: Contactado | L2: 45943 | M2: 45945 | N2: 45946 | O2: Rechazada | R2: No realizada | T2: Sí | U2: Presencial | Y2: Luego del ingreso por Mesa de Partes Virtual, delegaron a Ana Susana Cercado Silva, Fiscal Provincial de la Fiscalia Provincial Corporativa Especailizada en Delitos de Violencia contra las Mujeres y los Integrantes del Grupo Familiar - Cajamrca
A3: =A2+1 -> 2 | B3: Carmen Miranda Vidaurre | C3: Ministerio Público | D3: cmirandadj@mpfn.gob.pe | G3: Actores clave | H3: Funcionarios | I3: Nacional | J3: APOYO | K3: Contactado | L3: 45943 | M3: 45946 | N3: 45954 | O3: Rechazada | R3: No realizada | T3: Sí | U3: A distancia asistido | Y3: Se ingresó oficio por Mesa de Partes Virtual. Respondieron solicitando información detallada del estudio, incluso compartir instrumentos, e indicando que solo puede tener una duración de 10 minutos.
A4: =A3+1 -> 3 | B4: Marco de la Cruz Espejo | C4: Ministerio Público | D4: mdelacruzdj@mpfn.gob.pe | G4: Actores clave | H4: Funcionarios | I4: Nacional | J4: APOYO | K4: Contactado | L4: 45943 | M4: 45946 | N4: 45950 | O4: Sin respuesta | R4: No realizada | T4: Sí | U4: Autoadministrado | Y4: Se ingresó oficio por Mesa de Partes Virtual, en seguimiento.
A5: =A4+1 -> 4 | B5: Karen De Los Milagros Ucañan Cachy | C5: Centros de Acogida Residencial | D5: karen.uc7@hotmail.com | G5: Actores clave | H5: Actores locales | I5: Cajamarca | J5: APOYO | K5: Contactado | L5: 45943 | M5: 45945 | N5: 45946 | O5: Sin respuesta | R5: No realizada | T5: Sí | U5: Presencial | Y5: Pese a que brindó contacto y mostró disposición en la visita presencial, actualmente no responde.
A6: =A5+1 -> 5 | B6: María Barbara Venemans De Wilde | C6: Centros de Acogida Residencial | D6: alanyasantacruz@loscachorros.nl | G6: Actores clave | H6: Actores locales | I6: Ayacucho | J6: APOYO | K6: Contactado | L6: 45943 | M6: 45945 | N6: 45946 | O6: Rechazada | R6: No realizada | T6: Sí | U6: A distancia asistido | V6: A distancia asistido | Y6: María deriva a Delmir, Área promoción interinstitucional, para realizar entrevista 23/10.
A7: =A6+1 -> 6 | B7: María Magdalena Resurrección Valdivia | C7: Centros de Acogida Residencial | D7: car.pillcomozo@inabif.gob.pe | G7: Actores clave | H7: Actores locales | I7: Huánuco | J7: APOYO | K7: Contactado | L7: 45943 | M7: 45946 | O7: Realizada | P7: 45946 | Q7: 45946 | R7: Completa | S7: 14 | T7: Sí | U7: Autoadministrado | V7: Autoadministrado | Y7: -
A8: =A7+1 -> 7 | B8: Angie Vargas | C8: Manuela Ramos | E8: 985 062 650 (Rocío Gutíerrez, directora) | G8: Actores clave | H8: Actores locales | I8: Nacional | J8: IJM | K8: Contactado | L8: 45943 | O8: Sin respuesta | R8: No realizada | T8: Sí | U8: Presencial | Y8: Coordinación directa con IJM.
A9: =A8+1 -> 8 | B9: Intikilla Delgado | C9: Asociación Kallpa | D9: comunicaciones@kallpa.org.pe | G9: Actores clave | H9: Actores locales | I9: Nacional | J9: APOYO | K9: Contactado | L9: 45943 | O9: Sin respuesta | R9: No realizada | T9: Sí | U9: A distancia asistido | Y9: No se logró contacto por ningun medio, se reemplaza por Kathia Villar de AMAR C, en seguimiento.
A10: =A9+1 -> 9 | B10: Rosa Peña | C10: Kids Alive | D10: rosa.pena@kidsalive.org | G10: Actores clave | H10: Actores locales | I10: Ucayali | J10: APOYO | K10: Contactado | L10: 45943 | M10: 45946 | N10: 45951 | O10: Realizada | P10: 45951 | Q10: 45951 | R10: Completa | T10: Sí | U10: Autoadministrado | V10: Autoadministrado | Y10: Confirmó participación con IJM, se le envió cuestionario, aun sin respuesta.
A11: =A10+1 -> 10 | B11: Kelly Sopla Rojas | C11: CEM | D11: kellysopla_obst@yahoo.es | G11: Actores clave | H11: Acompañantes | I11: Lima Norte | J11: APOYO | K11: Contactado | L11: 45943 | M11: 45945 | N11: 45946 | O11: Realizada | P11: 45952 | Q11: 45952 | R11: Completa | T11: Sí | U11: Presencial | V11: A distancia asistido | Y11: Solciitó entrevista "virtual" y a título personal, no como CEM.
A12: =A11+1 -> 11 | B12: Felix Dulio Sobrado Chavez | C12: CEM | E12: 941526985 | G12: Actores clave | H12: Acompañantes | I12: Huánuco | J12: IJM | K12: Contactado | L12: 45943 | O12: Sin respuesta | R12: No realizada | T12: Sí | U12: A distancia asistido | Y12: Coordinación directa con IJM.
A13: =A12+1 -> 12 | B13: Silvio Mestanza Dominguez | C13: CEM | D13: silvio.mestanza@aurora.gob.pe | G13: Actores clave | H13: Acompañantes | I13: Loreto | J13: APOYO | K13: Contactado | L13: 45943 | M13: 45946 | N13: 45947 | O13: Sin respuesta | R13: No realizada | T13: Sí | U13: Autoadministrado | Y13: Solicitió ser contactado desde el 21/10, no respondió más, aparentemente bloqueó nuestros números. Se está intentando contacto con responsables del CEM Iquitos o CEM Nauta, como reemplazos.
A14: =A13+1 -> 13 | B14: Ana Susana Cercado Silva | C14: Ministerio Público | D14: - | E14: - | G14: Actores clave | H14: Funcionarios | I14: Cajamarca | J14: APOYO | K14: Contactado | O14: Realizada | P14: 45964 | Q14: 45964 | R14: Completa | S14: 60 | T14: No | U14: A distancia asistido | V14: A distancia asistido | Y14: Entrevistada fue derivada por Edgar Alfredo Rebaza Vargas
A15: =A14+1 -> 14 | B15: Luz Esperanza Rumay Cerna | C15: Centros de Acogida Residencial | G15: Actores clave | H15: Actores locales | I15: Cajamarca | J15: APOYO | K15: Contactado | L15: 45950 | M15: 45960 | N15: 45964 | O15: Realizada | P15: 45972 | R15: Completa | T15: No | U15: Presencial | V15: A distancia asistido
A16: =A15+1 -> 15 | B16: Delmir | C16: Centros de Acogida Residencial | G16: Actores clave | H16: Actores locales | I16: Ayacucho | J16: APOYO | K16: Contactado | L16: 45946 | O16: Realizada | P16: 45953 | Q16: 45953 | R16: Completa | S16: 60 | T16: No | U16: A distancia asistido | V16: A distancia asistido
A17: =A16+1 -> 16 | B17: Sobreviviente 1 | C17: n.a. | D17: n.a. | E17: n.a. | F17: n.a. | G17: Sobrevivientes y líderes sobrevivientes | H17: Sobreviviente | I17: Apurímac | J17: IJM | K17: Contactado | O17: Realizada | P17: 45951 | Q17: 45951 | R17: Completa | T17: n.a. | U17: Presencial | V17: Presencial
A18: =A17+1 -> 17 | B18: Sobreviviente 2 | C18: n.a. | D18: n.a. | E18: n.a. | F18: n.a. | G18: Sobrevivientes y líderes sobrevivientes | H18: Sobreviviente | I18: Apurímac | J18: IJM | K18: Contactado | O18: Realizada | P18: 45951 | Q18: 45951 | R18: Completa | T18: n.a. | U18: Presencial | V18: Presencial
A19: =A18+1 -> 18 | B19: Sobreviviente 3 | C19: n.a. | D19: n.a. | E19: n.a. | F19: n.a. | G19: Sobrevivientes y líderes sobrevivientes | H19: Sobreviviente | I19: Lima Norte | J19: IJM | K19: Contactado | O19: Realizada | P19: 45958 | Q19: 45958 | R19: Completa | T19: n.a. | U19: Presencial | V19: Presencial
A20: =A19+1 -> 19 | B20: Sobreviviente 4 | C20: n.a. | D20: n.a. | E20: n.a. | F20: n.a. | G20: Sobrevivientes y líderes sobrevivientes | H20: Sobreviviente | I20: Lima Norte | J20: IJM | K20: Contactado | O20: Realizada | P20: 45958 | Q20: 45958 | R20: Completa | T20: n.a. | U20: Presencial | V20: Presencial
A21: =A20+1 -> 20 | B21: Sobreviviente 5 | C21: n.a. | D21: n.a. | E21: n.a. | F21: n.a. | G21: Sobrevivientes y líderes sobrevivientes | H21: Sobreviviente | I21: Lima Norte | J21: IJM | K21: Contactado | O21: Realizada | P21: 45958 | Q21: 45958 | R21: Completa | T21: n.a. | U21: Presencial | V21: Presencial
A22: =A21+1 -> 21 | B22: Líder sobreviviente 1 | C22: n.a. | D22: n.a. | E22: n.a. | F22: n.a. | G22: Sobrevivientes y líderes sobrevivientes | H22: Líder sobreviviente | I22: Apurímac | J22: IJM | K22: Contactado | O22: Realizada | P22: 45951 | Q22: 45951 | R22: Completa | T22: n.a. | U22: Presencial | V22: Presencial

Sheet Reunión de validación
A1: Identificador | B1: Tipo de grupo focal | C1: Nombre | D1: Institución | E1: Correo | F1: Número | G1: Otro medio de contacto | H1: Tipo de actor | I1: Distrito judicial | J1: Encargado de contacto | K1: Medio de contacto | L1: Contacto | M1: Fecha de primer contacto | N1: Fecha de segundo contacto | O1: Fecha de tercer contacto | P1: Respuesta del actor | Q1: Fecha de grupo focal | R1: Asistencia al grupo focal | S1: Duración total (min) | T1: Observaciones
A2: 1 | B2: Reunión de validación | C2: Milagritos Llontop | D2: Defensa Pública | E2: illontop@minjus.gob.pe | H2: Instituciones públicas | I2: Nacional | J2: IJM | L2: Contactado | M2: 45943 | P2: Rechazada | Q2: 45959
A3: =A2+1 -> 2 | B3: Reunión de validación | C3: Victoria Pomalaya Trillo | D3: Ministerio Público | E3: vpomalaya@mpfn.gob.pe; victoriapomalaya@gmail.com | H3: Instituciones públicas | I3: Ucayali | J3: APOYO | L3: Contactado | M3: 45943 | N3: 45947 | O3: 45952 | P3: Rechazada | Q3: 45959 | T3: Indicó disposición. Su disponibilidad cambió por el estado de emergencia y, por lo tanto, incremento de actividades laborales de ella y su equipo completo durante distintos horarios no previstos.
A4: =A3+1 -> 3 | B4: Reunión de validación | C4: Katherine Olivera Rojas | D4: Programa Aurora | E4: kolivera@aurora.gob.pe | F4: 943602599 | H4: Instituciones públicas | I4: Nacional | J4: APOYO | L4: Contactado | M4: 45943 | N4: 45946 | P4: Aceptada | Q4: 45951 | R4: Asistió | S4: 83
A5: =A4+1 -> 4 | B5: Reunión de validación | C5: Estela Lozano Reyes | D5: Defensoría del Pueblo | E5: odcallao@defensoria.gob.pe | H5: Instituciones públicas | I5: Nacional | J5: APOYO | L5: Contactado | M5: 45943 | N5: 45947 | P5: Rechazada | Q5: 45959 | T5: En coordinación. Antes era "Delcy Yaniri Heredia". Indicó disposición, pero su disponibilidad cambió por el estado de emergencia y, por lo tanto, incremento de actividades laborales durante distintos horarios no previstos. No tiene a quien derivar.
A6: =A5+1 -> 5 | B6: Reunión de validación | C6: Beatriz Gamarra | D6: UNICEF | E6: bgamarra@unicef.org | H6: Multilaterales | I6: Nacional | J6: APOYO | L6: Contactado | M6: 45943 | N6: 45946 | P6: Aceptada | Q6: 45951 | R6: Asistió | S6: 83
A7: =A6+1 -> 6 | B7: Reunión de validación | C7: Amelia Cabrera | D7: World Vision Perú | E7: amelia_cabrera_salazar@wvi.org | H7: Multilaterales | I7: Nacional | J7: APOYO | L7: Contactado | M7: 45943 | N7: 45946 | O7: 45947 | P7: Aceptada | Q7: 45959 | R7: Asistió | S7: 93 | T7: Se complementará con una entrevista para indagar sobre el grupo focal de adolescentes entre lunes 10 y martes 11.
A8: =A7+1 -> 7 | B8: Reunión de validación | C8: Silvia Romero Borda | D8: GIZ | E8: silvia.romeroborda@giz.de | H8: Multilaterales | I8: Nacional | J8: APOYO | L8: Contactado | M8: 45943 | N8: 45947 | O8: 45954 | P8: Rechazada | Q8: 45959 | T8: Mostró disposición para participar, en horarios que se ajusten a su agenda.
A9: =A8+1 -> 8 | B9: Reunión de validación | C9: Magaly Arenas Astete | D9: Policía Nacional del Perú | F9: 997588413 | H9: Instituciones públicas | I9: Nacional | J9: IJM | L9: Contactado | M9: 45943 | P9: Aceptada | Q9: 45951 | R9: Asistió | S9: 83
A10: =A9+1 -> 9 | B10: Reunión de validación | C10: Eric León | D10: Policía Nacional del Perú | F10: 962723949 | H10: Instituciones públicas | I10: Nacional | J10: IJM | L10: Contactado | M10: 45943 | P10: Aceptada | Q10: 45959 | R10: Asistió | S10: 93
A11: =A10+1 -> 10 | B11: Reunión de validación | C11: Neil Avila | D11: Poder Judicial | F11: 964863586 | H11: Instituciones públicas | I11: Nacional | J11: IJM | L11: Contactado | M11: 45943 | P11: Aceptada | Q11: 45951 | R11: Asistió | S11: 83
A12: =A11+1 -> 11 | B12: Reunión de validación | C12: Norma Rojas | D12: Ministerio del Interior | F12: 993819250 | H12: Instituciones públicas | I12: Nacional | J12: IJM | L12: Contactado | M12: 45943 | P12: Rechazada | Q12: 45959
A13: =A12+1 -> 12 | B13: Reunión de validación | C13: Lourdes Febres Chirinos | D13: Acción Por los niños | F13: 995579501 | H13: ONG | I13: Nacional | J13: IJM | L13: Contactado | M13: 45943 | P13: Rechazada | Q13: 45959
A14: =A13+1 -> 13 | B14: Reunión de validación | C14: Maria Elena Bazán | D14: Centros de Acogida Residencial | F14: 3817190 | H14: Instituciones públicas | I14: Lima Norte | J14: IJM | L14: Contactado | M14: 45943 | P14: Rechazada | Q14: 45959
A15: =A14+1 -> 14 | B15: Reconocimiento - 1 | C15: Cinthia Navarro | D15: Oxfam | E15: alexandra.alayza@oxfam.org | H15: Multilaterales | I15: Nacional | J15: IJM | K15: Correo | L15: Contactado | P15: Sin respuesta
A16: =A15+1 -> 15 | B16: Reconocimiento - 1 | C16: Sofía García | D16: IPRODES | E16: comunicaciones@iprodes.org | H16: Multilaterales | I16: Nacional | J16: IJM | K16: Correo | L16: Contactado | P16: Sin respuesta
A17: =A16+1 -> 16 | B17: Reconocimiento - 1 | C17: Jenny Dador | D17: Coordinadora de Derechos Humanos | F17: 953297789 | H17: ONG | I17: Nacional | J17: IJM | K17: WhatsApp | L17: Contactado | P17: En coordinación | T17: Se encuentra interesada en participar. Volver a consultar disponibilidad.
A18: =A17+1 -> 17 | B18: Reconocimiento - 1 | C18: Carol Tremont | D18: Asociación Protección Población Vulnerable | E18: info@appv.pe | H18: ONG | I18: Nacional | J18: IJM | K18: Correo (correo no se envió con éxito, por algún problema con su correo institucional) | L18: No contactado | P18: Sin respuesta
A19: =A18+1 -> 18 | B19: Reconocimiento - 1 | C19: Rosario Cosar | D19: Asociación Kallpa | E19: comunicaciones@kallpa.org.pe | H19: ONG | I19: Lima Norte | J19: IJM | K19: Correo | L19: Contactado | P19: Sin respuesta
A20: =A19+1 -> 19 | B20: Reconocimiento - 1 | C20: Oscar Andrés Alva Arías | D20: MIMP | E20: mesadepartesdigital@mimp.gob.pe | H20: Instituciones públicas | I20: Nacional | J20: IJM | K20: Correo, carta entregada a la mesa de partes (en trámite) | L20: Contactado | P20: Sin respuesta
A21: =A20+1 -> 20 | B21: Reconocimiento - 1 | C21: Silvia Arteaga | D21: Centros de Acogida Residencial | E21: car.sricardo@inabif.gob.pe | H21: Instituciones públicas | I21: Lime Este | J21: IJM | K21: Correo | L21: Contactado | P21: Sin respuesta
A22: =A21+1 -> 21 | B22: Reconocimiento - 1 | C22: Angel Grimaldo Palacios Trujillo | D22: CEM | E22: asistenciaeconomica@waminam.gob.pe | H22: Instituciones públicas | I22: Lima Norte | J22: IJM | K22: Entregada a la mesa de partes (en trámite) | L22: Contactado | P22: Sin respuesta
A23: =A22+1 -> 22 | B23: Reconocimiento - 1 | C23: Helen Arlene Maza Gonzales | D23: CEM | E23: helen.maza@waminam.gob.pe | H23: Instituciones públicas | I23: Puente Piedra - Ventanilla | J23: IJM | K23: Randall está coordinando por WhatsApp con una empleada del CEM Ventanilla para transmitirla la carta | L23: Contactado | P23: Aceptada | Q23: 46001 | R23: Asistió | S23: 120 | T23: Enviar detalles del GF a su correo
A24: =A23+1 -> 23 | B24: Reconocimiento - 1 | C24: Magaly Blas | D24: Colegio Médico del Perú | E24: magaly.blas.b@upch.pe | H24: Instituciones públicas | I24: Nacional | J24: IJM | K24: Correo | L24: Contactado | P24: Sin respuesta
A25: =A24+1 -> 24 | B25: Reconocimiento - 1 | C25: Eutropia Ayllon León de Lima Norte | D25: Orientadora Judicial | F25: 922275280 | H25: Líderes comunitarios | I25: Lima Norte | J25: IJM | K25: WhatsApp | L25: Contactado | P25: Aceptada | Q25: 46001 | R25: No asistió | T25: Enviar detalles del GF a su número celular
A26: =A25+1 -> 25 | B26: Reconocimiento - 1 | C26: Carmen Rosa Villela Vargas | D26: Orientadora Judicial | F26: 967806708 | H26: Líderes comunitarios | I26: Lima | J26: IJM | K26: WhatsApp | L26: Contactado | P26: Aceptada | Q26: 46001 | R26: No asistió | T26: Enviar detalles del GF a su número celular
A27: =A26+1 -> 26 | B27: Reconocimiento - 1 | C27: Arlette Contreras | D27: Ni una menos | E27: arlettecontreras@agendamujer.com | H27: Líderes comunitarios | I27: Lima | J27: IJM | K27: Correo | L27: Contactado | P27: Sin respuesta
A28: =A27+1 -> 27 | B28: Reconocimiento - 1 | C28: Katherine Flores Mendoza | D28: Familias Unidas Por Justicia: Familiares de Víctimas de Feminicidio | E28: familiasunidasporjusticia@gmail.com | F28: 976617075 | H28: Líderes comunitarios | I28: Nacional | J28: IJM | K28: Correo | L28: Contactado | P28: Aceptada | Q28: 46001 | R28: Asistió | S28: 120 | T28: Enviar detalles del GF a su número celular
A29: =A28+1 -> 28 | B29: Reconocimiento - 1 | C29: Judith Gisella Caruhapoma Ortega | D29: Ministerio Público | E29: mp.1d.1fvcm.ci@mpfn.gob.pe | H29: Instituciones públicas | I29: Lima Norte | J29: IJM | K29: Correo | L29: Contactado | P29: Sin respuesta
A30: =A29+1 -> 29 | B30: Reconocimiento - 1 | C30: Vanessa Díaz | D30: Wami Ñan | E30: vanessa.diaz@waminam.gob.pe | F30: 927698304 | H30: Instituciones públicas | I30: Lima | J30: IJM | K30: Correo | L30: Contactado | P30: Aceptada | Q30: 46001 | R30: Asistió | S30: 120 | T30: Enviar detalles del GF al correo
A31: =A30+1 -> 30 | B31: Reconocimiento - 1 | C31: Zoila Cabanillas | D31: Wami Ñan | E31: zoila.cabanillas@waminam.gob.pe | F31: 994581446 | H31: Instituciones públicas | I31: Lima | J31: IJM | K31: Correo | L31: Contactado | P31: Aceptada | Q31: 46001 | R31: No asistió | T31: Enviar detalles del GF al correo

Sheet Listas
A1: Respuestas | B1: Contacto | C1: Distrito Judicial | D1: Asistencia | E1: Tipo de actor (confianza) | F1: Tipo de actor (gf) | G1: Modalidad | H1: Resultado | I1: Slección
A2: Aceptada | B2: Contactado | C2: Lima Norte | D2: Asistió | E2: Funcionarios | F2: Instituciones públicas | G2: Presencial | H2: Completa | I2: Sí
A3: Rechazada | B3: No contactado | C3: Puente Piedra - Ventanilla | D3: No asistió | E3: Actores locales | F3: Multilaterales | G3: A distancia asistido | H3: Incompleta | I3: No
A4: Sin respuesta | C4: Apurímac | D4: Por definir | E4: Acompañantes | F4: ONG | G4: Autoadministrado | H4: No realizada
A5: En coordinación | C5: Huánuco | E5: Multilaterales | F5: Líderes comunitarios | G5: No aplica
C6: Ucayali | E6: Prensa | F6: Otros
C7: Loreto
C8: Cajamarca
C9: Ayacucho
C10: Nacional

Sheet Insumos Dashboard >>

Sheet Dashboard - Entrevistas(0)
A1: Identificador | B1: Nombre | C1: Institución | D1: Tipo de entrevistas | E1: Meta | F1: Tipo de actor | G1: Distrito judicial | H1: Encargado de contacto | I1: Contacto | J1: Fecha de primer contacto | K1: Fecha de segundo contacto | L1: Fecha de tercer contacto | M1: Respuesta del actor | N1: Fecha de inicio de entrevista | O1: Fecha de fin de entrevista | P1: Resultado | Q1: Duración total (min) | R1: Actor considerado inicialmente | S1: Modalidad establecida | T1: Modalidad aplicada | U1: Dummy Contacto | V1: Dummy coordinación | W1: Dummy aceptada | X1: Dummy realizada | Y1: Dummy sin respuesta
A2: =IF(Entrevistas!A2="","",Entrevistas!A2) -> 1 | B2: =IF(Entrevistas!B2="","",Entrevistas!B2) -> Edgar Alfredo Rebaza Vargas | C2: =IF(Entrevistas!C2="","",Entrevistas!C2) -> Ministerio Público | D2: =IF(Entrevistas!G2="","",Entrevistas!G2) -> Actores clave | E2: =+INDEX(Meta!$C$2:$E$6,MATCH(F2,Meta!$C$2:$C$6,0),2) -> #N/A | F2: =IF(Entrevistas!H2="","",Entrevistas!H2) -> Funcionarios | G2: =IF(Entrevistas!I2="","",Entrevistas!I2) -> Cajamarca | H2: =IF(Entrevistas!J2="","",Entrevistas!J2) -> APOYO | I2: =IF(Entrevistas!K2="","",Entrevistas!K2) -> Contactado | J2: =IF(Entrevistas!L2="","",Entrevistas!L2) -> 45943 | K2: =IF(Entrevistas!M2="","",Entrevistas!M2) -> 45945 | L2: =IF(Entrevistas!N2="","",Entrevistas!N2) -> 45946 | M2: =IF(Entrevistas!O2="","",Entrevistas!O2) -> Rechazada | ... T2: =IF(Entrevistas!V2="","",Entrevistas!V2) | U2: =IF(I2="Contactado",1,0) -> 1 | V2: =IF(M2="En coordinación",1,0) -> 0 | W2: =IF(M2="Aceptada",1,0) -> 0 | X2: =IF(M2="Realizada",1,0) -> 0 | Y2: =IF(M2="Sin respuesta",1,0) -> 0
