Workbook

Sheet Bases >>

Sheet GF
A1: Tipo | B1: Identificador | C1: Fecha de contacto | D1: Distrito Judicial | E1: Departamento | F1: Sexo | G1: Contacto | H1: Coordinación | I1: Tipo de actor | J1: Asistencia
A2: Reconocimiento | B2: 12456 | C2: 45927 | D2: Cajamarca | E2: Cajamarca | F2: Hombre | G2: Contactado | H2: Coordinada | I2: Otros | J2: =IF(H2="Coordinada","Asistió","No asistió") -> Asistió
A3: Profundización | B3: 12457 | C3: 45918 | D3: Ayacucho | E3: Ayacucho | F3: Mujer | G3: Contactado | H3: No coordinada | I3: Funcionario/a | J3: =IF(H3="Coordinada","Asistió","No asistió") -> No asistió
A4: Adolescentes | B4: 12458 | C4: 45924 | D4: Resto del Perú | E4: Pasco | F4: Hombre | G4: Contactado | H4: Coordinada | I4: Sobreviviente | J4: =IF(H4="Coordinada","Asistió","No asistió") -> Asistió
A5: Reconocimiento | B5: 12459 | C5: 45926 | D5: Apurímac | E5: Apurímac | F5: Hombre | G5: Contactado | H5: No coordinada | I5: ONG | J5: =IF(H5="Coordinada","Asistió","No asistió") -> No asistió
A6: Profundización | B6: 12460 | C6: 45927 | D6: Lima Norte | E6: Lima | F6: Mujer | G6: Contactado | H6: Coordinada | I6: ONG | J6: =IF(H6="Coordinada","Asistió","No asistió") -> Asistió
A7: Adolescentes | B7: 12461 | C7: 45923 | D7: Apurímac | E7: Apurímac | F7: Mujer | G7: Contactado | H7: Coordinada | I7: Líder sobreviviente | J7: =IF(H7="Coordinada","Asistió","No asistió") -> Asistió
A8: Reconocimiento | B8: 12462 | C8: 45923 | D8: Ayacucho | E8: Ayacucho | F8: Hombre | G8: Contactado | H8: No coordinada | I8: Funcionario/a | J8: =IF(H8="Coordinada","Asistió","No asistió") -> No asistió
A9: Profundización | B9: 12463 | C9: . | D9: Cajamarca | E9: Cajamarca | F9: Mujer | G9: No contactado | H9: . | I9: Otros | J9: =IF(H9="Coordinada","Asistió","No asistió") -> No asistió
A10: Reconocimiento | B10: 12464 | C10: 45922 | D10: Huánuco | E10: Huánuco | F10: Hombre | G10: Contactado | H10: No coordinada | I10: ONG | J10: =IF(H10="Coordinada","Asistió","No asistió") -> No asistió
A11: Reconocimiento | B11: 12465 | C11: 45918 | D11: Resto del Perú | E11: Lambayeque | F11: Hombre | G11: Contactado | H11: Rechazada | I11: Funcionario/a | J11: =IF(H11="Coordinada","Asistió","No asistió") -> No asistió
A12: Profundización | B12: 12466 | C12: 45928 | D12: Apurímac | E12: Apurímac | F12: Hombre | G12: Contactado | H12: Rechazada | I12: ONG | J12: =IF(H12="Coordinada","Asistió","No asistió") -> No asistió
A13: Reconocimiento | B13: 12467 | C13: 45919 | D13: Huánuco | E13: Huánuco | F13: Mujer | G13: Contactado | H13: No coordinada | I13: ONG | J13: =IF(H13="Coordinada","Asistió","No asistió") -> No asistió
A14: Profundización | B14: 12468 | C14: 45923 | D14: Puente Piedra-Ventanilla | E14: Lima | F14: Hombre | G14: Contactado | H14: No coordinada | I14: Funcionario/a | J14: =IF(H14="Coordinada","Asistió","No asistió") -> No asistió
A15: Reconocimiento | B15: 12469 | C15: 45923 | D15: Loreto | E15: Loreto | F15: Hombre | G15: Contactado | H15: Rechazada | I15: ONG | J15: =IF(H15="Coordinada","Asistió","No asistió") -> No asistió
A16: Profundización | B16: 12470 | C16: . | D16: Ayacucho | E16: Ayacucho | F16: Hombre | G16: No contactado | H16: . | I16: Otros | J16: =IF(H16="Coordinada","Asistió","No asistió") -> No asistió
A17: Adolescentes | B17: 12471 | C17: 45921 | D17: Ayacucho | E17: Ayacucho | F17: Hombre | G17: Contactado | H17: Coordinada | I17: Sobreviviente | J17: =IF(H17="Coordinada","Asistió","No asistió") -> Asistió
A18: Adolescentes | B18: 12472 | C18: . | D18: Ayacucho | E18: Ayacucho | F18: Hombre | G18: No contactado | H18: . | I18: Sobreviviente | J18: =IF(H18="Coordinada","Asistió","No asistió") -> No asistió
A19: Profundización | B19: 12473 | C19: 45916 | D19: Puente Piedra-Ventanilla | E19: Lima | F19: Hombre | G19: Contactado | H19: No coordinada | I19: Funcionario/a | J19: =IF(H19="Coordinada","Asistió","No asistió") -> No asistió
A20: Reconocimiento | B20: 12474 | C20: 45921 | D20: Huánuco | E20: Huánuco | F20: Hombre | G20: Contactado | H20: Coordinada | I20: ONG | J20: =IF(H20="Coordinada","Asistió","No asistió") -> Asistió
A21: Adolescentes | B21: 12475 | C21: 45927 | D21: Cajamarca | E21: Cajamarca | F21: Hombre | G21: Contactado | H21: Rechazada | I21: Líder sobreviviente | J21: =IF(H21="Coordinada","Asistió","No asistió") -> No asistió
A22: Profundización | B22: 12476 | C22: . | D22: Ayacucho | E22: Ayacucho | F22: Mujer | G22: No contactado | H22: . | I22: Funcionario/a | J22: =IF(H22="Coordinada","Asistió","No asistió") -> No asistió
A23: Reconocimiento | B23: 12477 | C23: 45925 | D23: Resto del Perú | E23: Ica | F23: Hombre | G23: Contactado | H23: Coordinada | I23: Funcionario/a | J23: =IF(H23="Coordinada","Asistió","No asistió") -> Asistió
A24: Adolescentes | B24: 12478 | C24: . | D24: Ucayali | E24: Ucayali | F24: Mujer | G24: No contactado | H24: . | I24: Sobreviviente | J24: =IF(H24="Coordinada","Asistió","No asistió") -> No asistió
A25: Profundización | B25: 12479 | C25: 45916 | D25: Apurímac | E25: Apurímac | F25: Mujer | G25: Contactado | H25: No coordinada | I25: Funcionario/a | J25: =IF(H25="Coordinada","Asistió","No asistió") -> No asistió
A26: Adolescentes | B26: 12480 | C26: . | D26: Apurímac | E26: Apurímac | F26: Mujer | G26: No contactado | H26: . | I26: Sobreviviente | J26: =IF(H26="Coordinada","Asistió","No asistió") -> No asistió
A27: Profundización | B27: 12481 | C27: 45924 | D27: Ucayali | E27: Ucayali | F27: Mujer | G27: Contactado | H27: Coordinada | I27: ONG | J27: =IF(H27="Coordinada","Asistió","No asistió") -> Asistió
A28: Adolescentes | B28: 12482 | C28: 45926 | D28: Ayacucho | E28: Ayacucho | F28: Mujer | G28: Contactado | H28: Rechazada | I28: Sobreviviente | J28: =IF(H28="Coordinada","Asistió","No asistió") -> No asistió
A29: Profundización | B29: 12483 | C29: . | D29: Lima Norte | E29: Lima | F29: Mujer | G29: No contactado | H29: . | I29: Otros | J29: =IF(H29="Coordinada","Asistió","No asistió") -> No asistió
A30: Reconocimiento | B30: 12484 | C30: 45924 | D30: Puente Piedra-Ventanilla | E30: Lima | F30: Hombre | G30: Contactado | H30: No coordinada | I30: ONG | J30: =IF(H30="Coordinada","Asistió","No asistió") -> No asistió
A31: Reconocimiento | B31: 12485 | C31: 45922 | D31: Lima Norte | E31: Lima | F31: Hombre | G31: Contactado | H31: Coordinada | I31: Otros | J31: =IF(H31="Coordinada","Asistió","No asistió") -> Asistió

Sheet Entrevistas
A1: Identificador | B1: Tipo de entrevista | C1: Tipo de actor | D1: Fecha de contacto | E1: Distrito Judicial | F1: Departamento | G1: Contacto | H1: Coordinación | I1: Rol | J1: Fecha de entrevista | K1: Resultado | L1: Duración (min)
A2: 12456 | B2: Sobrevivientes y líderes sobrevivientes | C2: n.a. | D2: . | E2: Cajamarca | F2: Cajamarca | G2: No contactado | H2: . | I2: Líder sobreviviente | J2: . | K2: . | L2: 44
A3: =A2+1 -> 12457 | B3: Sobrevivientes y líderes sobrevivientes | C3: n.a. | D3: 45930 | E3: Ayacucho | F3: Ayacucho | G3: Contactado | H3: No coordinada | I3: Sobreviviente | J3: . | K3: . | L3: 48
A4: =A3+1 -> 12458 | B4: Sobrevivientes y líderes sobrevivientes | C4: n.a. | D4: 45929 | E4: Resto del Perú | F4: Pasco | G4: Contactado | H4: Coordinada | I4: Sobreviviente | J4: 45960 | K4: Completa | L4: 50
A5: =A4+1 -> 12459 | B5: Sobrevivientes y líderes sobrevivientes | C5: n.a. | D5: 45925 | E5: Apurímac | F5: Apurímac | G5: Contactado | H5: No coordinada | I5: Líder sobreviviente | J5: . | K5: . | L5: 48
A6: =A5+1 -> 12460 | B6: Sobrevivientes y líderes sobrevivientes | C6: n.a. | D6: 45928 | E6: Lima Norte | F6: Lima | G6: Contactado | H6: Coordinada | I6: Sobreviviente | J6: 45948 | K6: Completa | L6: 44
A7: =A6+1 -> 12461 | B7: Sobrevivientes y líderes sobrevivientes | C7: n.a. | D7: 45917 | E7: Apurímac | F7: Apurímac | G7: Contactado | H7: Coordinada | I7: Sobreviviente | J7: 45945 | K7: Incompleta | L7: 31
A8: =A7+1 -> 12462 | B8: Sobrevivientes y líderes sobrevivientes | C8: n.a. | D8: 45920 | E8: Ayacucho | F8: Ayacucho | G8: Contactado | H8: No coordinada | I8: Sobreviviente | J8: . | K8: . | L8: 36
A9: =A8+1 -> 12463 | B9: Sobrevivientes y líderes sobrevivientes | C9: n.a. | D9: 45923 | E9: Cajamarca | F9: Cajamarca | G9: Contactado | H9: Rechazada | I9: Sobreviviente | J9: . | K9: . | L9: 43
A10: =A9+1 -> 12464 | B10: Sobrevivientes y líderes sobrevivientes | C10: n.a. | D10: 45921 | E10: Huánuco | F10: Huánuco | G10: Contactado | H10: No coordinada | I10: Líder sobreviviente | J10: . | K10: . | L10: 30
A11: =A10+1 -> 12465 | B11: Sobrevivientes y líderes sobrevivientes | C11: n.a. | D11: . | E11: Resto del Perú | F11: Lambayeque | G11: No contactado | H11: . | I11: Líder sobreviviente | J11: . | K11: . | L11: 33
A12: =A11+1 -> 12466 | B12: Sobrevivientes y líderes sobrevivientes | C12: n.a. | D12: 45925 | E12: Apurímac | F12: Apurímac | G12: Contactado | H12: Rechazada | I12: Sobreviviente | J12: . | K12: . | L12: 50
A13: =A12+1 -> 12467 | B13: Sobrevivientes y líderes sobrevivientes | C13: n.a. | D13: 45926 | E13: Huánuco | F13: Huánuco | G13: Contactado | H13: No coordinada | I13: Sobreviviente | J13: . | K13: . | L13: 30
A14: =A13+1 -> 12468 | B14: Sobrevivientes y líderes sobrevivientes | C14: n.a. | D14: 45916 | E14: Puente Piedra-Ventanilla | F14: Lima | G14: Contactado | H14: No coordinada | I14: Líder sobreviviente | J14: . | K14: . | L14: 37
A15: =A14+1 -> 12469 | B15: Sobrevivientes y líderes sobrevivientes | C15: n.a. | D15: . | E15: Loreto | F15: Loreto | G15: No contactado | H15: . | I15: Sobreviviente | J15: . | K15: . | L15: 33
A16: =A15+1 -> 12470 | B16: Sobrevivientes y líderes sobrevivientes | C16: n.a. | D16: . | E16: Ayacucho | F16: Ayacucho | G16: No contactado | H16: . | I16: Sobreviviente | J16: . | K16: . | L16: 36
A17: =A16+1 -> 12471 | B17: Sobrevivientes y líderes sobrevivientes | C17: n.a. | D17: 45927 | E17: Ayacucho | F17: Ayacucho | G17: Contactado | H17: Coordinada | I17: Sobreviviente | J17: 45959 | K17: Completa | L17: 35
A18: =A17+1 -> 12472 | B18: Sobrevivientes y líderes sobrevivientes | C18: n.a. | D18: . | E18: Ayacucho | F18: Ayacucho | G18: No contactado | H18: . | I18: Líder sobreviviente | J18: . | K18: . | L18: 31
A19: =A18+1 -> 12473 | B19: Sobrevivientes y líderes sobrevivientes | C19: n.a. | D19: 45923 | E19: Puente Piedra-Ventanilla | F19: Lima | G19: Contactado | H19: No coordinada | I19: Sobreviviente | J19: . | K19: . | L19: 30
A20: =A19+1 -> 12474 | B20: Sobrevivientes y líderes sobrevivientes | C20: n.a. | D20: . | E20: Huánuco | F20: Huánuco | G20: No contactado | H20: . | I20: Sobreviviente | J20: . | K20: . | L20: 34
A21: =A20+1 -> 12475 | B21: Sobrevivientes y líderes sobrevivientes | C21: n.a. | D21: 45928 | E21: Cajamarca | F21: Cajamarca | G21: Contactado | H21: Rechazada | I21: Sobreviviente | J21: . | K21: . | L21: 32
A22: =A21+1 -> 12476 | B22: Sobrevivientes y líderes sobrevivientes | C22: n.a. | D22: 45930 | E22: Ayacucho | F22: Ayacucho | G22: Contactado | H22: Rechazada | I22: Líder sobreviviente | J22: . | K22: . | L22: 43
A23: =A22+1 -> 12477 | B23: Sobrevivientes y líderes sobrevivientes | C23: n.a. | D23: 45929 | E23: Resto del Perú | F23: Ica | G23: Contactado | H23: Coordinada | I23: Líder sobreviviente | J23: 45960 | K23: Completa | L23: 32
A24: =A23+1 -> 12478 | B24: Sobrevivientes y líderes sobrevivientes | C24: n.a. | D24: . | E24: Ucayali | F24: Ucayali | G24: No contactado | H24: . | I24: Sobreviviente | J24: . | K24: . | L24: 49
A25: =A24+1 -> 12479 | B25: Sobrevivientes y líderes sobrevivientes | C25: n.a. | D25: 45916 | E25: Apurímac | F25: Apurímac | G25: Contactado | H25: No coordinada | I25: Sobreviviente | J25: . | K25: . | L25: 46
A26: =A25+1 -> 12480 | B26: Sobrevivientes y líderes sobrevivientes | C26: n.a. | D26: . | E26: Apurímac | F26: Apurímac | G26: No contactado | H26: . | I26: Sobreviviente | J26: . | K26: . | L26: 33
A27: =A26+1 -> 12481 | B27: Sobrevivientes y líderes sobrevivientes | C27: n.a. | D27: 45926 | E27: Ucayali | F27: Ucayali | G27: Contactado | H27: Coordinada | I27: Sobreviviente | J27: 45954 | K27: Completa
A28: =A27+1 -> 12482 | B28: Sobrevivientes y líderes sobrevivientes | C28: n.a. | D28: 45920 | E28: Ayacucho | F28: Ayacucho | G28: Contactado | H28: Rechazada | I28: Líder sobreviviente | J28: . | K28: . | L28: 48
A29: =A28+1 -> 12483 | B29: Sobrevivientes y líderes sobrevivientes | C29: n.a. | D29: 45919 | E29: Lima Norte | F29: Lima | G29: Contactado | H29: No coordinada | I29: Sobreviviente | J29: . | K29: . | L29: 41
A30: =A29+1 -> 12484 | B30: Sobrevivientes y líderes sobrevivientes | C30: n.a. | D30: . | E30: Puente Piedra-Ventanilla | F30: Lima | G30: No contactado | H30: . | I30: Sobreviviente | J30: . | K30: . | L30: 38
A31: =A30+1 -> 12485 | B31: Sobrevivientes y líderes sobrevivientes | C31: n.a. | D31: 45920 | E31: Lima Norte | F31: Lima | G31: Contactado | H31: Coordinada | I31: Líder sobreviviente | J31: 45951 | K31: Completa | L31: 48
A32: =A31+1 -> 12486 | B32: Sobrevivientes y líderes sobrevivientes | C32: n.a. | D32: 45917 | E32: Ayacucho | F32: Ayacucho | G32: Contactado | H32: Coordinada | I32: Sobreviviente | J32: 45955 | K32: Completa | L32: 34
A33: =A32+1 -> 12487 | B33: Sobrevivientes y líderes sobrevivientes | C33: n.a. | D33: . | E33: Ayacucho | F33: Ayacucho | G33: No contactado | H33: . | I33: Sobreviviente | J33: . | K33: . | L33: 48
A34: =A33+1 -> 12488 | B34: Sobrevivientes y líderes sobrevivientes | C34: n.a. | D34: 45929 | E34: Puente Piedra-Ventanilla | F34: Lima | G34: Contactado | H34: No coordinada | I34: Sobreviviente | J34: . | K34: . | L34: 33
A35: =A34+1 -> 12489 | B35: Sobrevivientes y líderes sobrevivientes | C35: n.a. | D35: 45918 | E35: Huánuco | F35: Huánuco | G35: Contactado | H35: Coordinada | I35: Sobreviviente | J35: 45958 | K35: Completa | L35: 37
A36: =A35+1 -> 12490 | B36: Sobrevivientes y líderes sobrevivientes | C36: n.a. | D36: . | E36: Cajamarca | F36: Cajamarca | G36: No contactado | H36: . | I36: Sobreviviente | J36: . | K36: . | L36: 40
A37: =A36+1 -> 12491 | B37: Sobrevivientes y líderes sobrevivientes | C37: n.a. | D37: 45929 | E37: Ayacucho | F37: Ayacucho | G37: Contactado | H37: Rechazada | I37: Sobreviviente | J37: . | K37: . | L37: 37
A38: =A37+1 -> 12492 | B38: Sobrevivientes y líderes sobrevivientes | C38: n.a. | D38: 45922 | E38: Resto del Perú | F38: Ica | G38: Contactado | H38: Coordinada | I38: Líder sobreviviente | J38: 45952 | K38: Completa | L38: 31
A39: =A38+1 -> 12493 | B39: Sobrevivientes y líderes sobrevivientes | C39: n.a. | D39: . | E39: Ucayali | F39: Ucayali | G39: No contactado | H39: . | I39: Sobreviviente | J39: . | K39: . | L39: 43
A40: =A39+1 -> 12494 | B40: Sobrevivientes y líderes sobrevivientes | C40: n.a. | D40: 45915 | E40: Apurímac | F40: Apurímac | G40: Contactado | H40: No coordinada | I40: Líder sobreviviente | J40: . | K40: . | L40: 50
...

Sheet Expedientes
A1: Identificador | B1: Fecha-Inicio | C1: Hora-Inicio | D1: Fecha-fin | E1: Hora-Fin | F1: Duración | G1: Revisor | H1: Distrito Judicial | I1: Departamento | J1: Tipo | K1: Contador
A2: 12456 | B2: 45930 | C2: 0.375 | D2: =B2 -> 45930 | E2: 0.45833333 | F2: =(E2-C2)*24*60 -> 120 | G2: 4 | H2: Cajamarca | I2: Cajamarca | J2: Violencia sexual | K2: 1
A3: =A2+1 -> 12457 | B3: 45930 | C3: 0.375 | D3: =B3 -> 45930 | E3: 0.45833333 | F3: =(E3-C3)*24*60 -> 120 | G3: 7 | H3: Ayacucho | I3: Ayacucho | J3: Violencia física | K3: 1
A4: =A3+1 -> 12458 | B4: 45929 | C4: 0.375 | D4: =B4 -> 45929 | E4: 0.45833333 | F4: =(E4-C4)*24*60 -> 120 | G4: 8 | H4: Ayacucho | I4: Ayacucho | J4: Violencia física | K4: 1
A5: =A4+1 -> 12459 | B5: 45925 | C5: 0.375 | D5: =B5 -> 45925 | E5: 0.45833333 | F5: =(E5-C5)*24*60 -> 120 | G5: 8 | H5: Huánuco | I5: Huánuco | J5: Violencia física | K5: 1
A6: =A5+1 -> 12460 | B6: 45928 | C6: 0.375 | D6: =B6 -> 45928 | E6: 0.45833333 | F6: =(E6-C6)*24*60 -> 120 | G6: 1 | H6: Ayacucho | I6: Ayacucho | J6: Feminicidio | K6: 1
A7: =A6+1 -> 12461 | B7: 45917 | C7: 0.375 | D7: =B7 -> 45917 | E7: 0.45833333 | F7: =(E7-C7)*24*60 -> 120 | G7: 6 | H7: Apurímac | I7: Apurímac | J7: Violencia física | K7: 1
A8: =A7+1 -> 12462 | B8: 45920 | C8: 0.375 | D8: =B8 -> 45920 | E8: 0.45833333 | F8: =(E8-C8)*24*60 -> 120 | G8: 5 | H8: Apurímac | I8: Apurímac | J8: Violencia física | K8: 1
A9: =A8+1 -> 12463 | B9: 45923 | C9: 0.375 | D9: =B9 -> 45923 | E9: 0.45833333 | F9: =(E9-C9)*24*60 -> 120 | G9: 3 | H9: Huánuco | I9: Huánuco | J9: Violencia física | K9: 1
A10: =A9+1 -> 12464 | B10: 45921 | C10: 0.375 | D10: =B10 -> 45921 | E10: 0.45833333 | F10: =(E10-C10)*24*60 -> 120 | G10: 8 | H10: Cajamarca | I10: Cajamarca | J10: Violencia física | K10: 1
A11: =A10+1 -> 12465 | B11: 45921 | C11: 0.375 | D11: =B11 -> 45921 | E11: 0.45833333 | F11: =(E11-C11)*24*60 -> 120 | G11: 3 | H11: Resto del Perú | I11: Resto del Perú | J11: Violencia sexual | K11: 1
A12: =A11+1 -> 12466 | B12: 45925 | C12: 0.375 | D12: =B12 -> 45925 | E12: 0.45833333 | F12: =(E12-C12)*24*60 -> 120 | G12: 6 | H12: Ucayali | I12: Ucayali | J12: Violencia física | K12: 1
A13: =A12+1 -> 12467 | B13: 45926 | C13: 0.375 | D13: =B13 -> 45926 | E13: 0.45833333 | F13: =(E13-C13)*24*60 -> 120 | G13: 3 | H13: Apurímac | I13: Apurímac | J13: Violencia física | K13: 1
A14: =A13+1 -> 12468 | B14: 45916 | C14: 0.375 | D14: =B14 -> 45916 | E14: 0.45833333 | F14: =(E14-C14)*24*60 -> 120 | G14: 2 | H14: Lima Norte | I14: Lima Norte | J14: Violencia física | K14: 1
... A50: =A49+1 -> 12504 | B50: 45915 | C50: 0.375 | D50: =B50 -> 45915 | E50: 0.45833333 | F50: =(E50-C50)*24*60 -> 120 | G50: 5 | H50: Huánuco | I50: Huánuco | J50: Violencia física | K50: 1

Sheet Insumos >>

Sheet Aleatorio
A1: Fecha de encuesta | B1: DDJJ | C1: Grupo etario | D1: Departamento | E1: Sexo | F1: Edad | G1: Resultado | H1: Violencia física | I1: Violencia sexual | J1: Denuncia | K1: Inicio | L1: Fin | M1: Latitud | N1: Longitud
A2: =+RANDBETWEEN(Apoyo!$P$2,Apoyo!$P$3) -> 45945 | B2: {=+INDEX(Apoyo!$B$2:$B$10,RANDBETWEEN(1,9))} -> Ayacucho | C2: Mujer | D2: {=+IF(OR($B2=Apoyo!$B$2,$B2=Apoyo!$B$6),"Lima",IF($B2=Apoyo!$B$10,INDEX(Apoyo!$D$2:$D$19,RANDBETWEEN(1,18)),IF(OR($B2<>Apoyo!$B$10,$B2<>Apoyo!$B$2,$B2<>Apoyo!$B$6),B2,0)))} -> Ayacucho | E2: =+IF(C2="Mujer","Femenino",2) -> Femenino | F2: =+IF(C2="Mujer",RANDBETWEEN(18,65),RANDBETWEEN(12,17)) -> 32 | G2: Completa | H2: =+IF($G2<>"Completa",IF($G2<>"Discapacidad",0,RANDBETWEEN(0,1)),RANDBETWEEN(0,1)) -> 0 | I2: =+IF($G2<>"Completa",IF($G2<>"Discapacidad",0,RANDBETWEEN(0,1)),RANDBETWEEN(0,1)) -> 0 | J2: =+IF(OR(H2=1,I2=1),RANDBETWEEN(0,1),0) -> 0 | K2: =IF(G2<>"Completa","n.a.",RAND()) -> 0.42833557 | L2: =+IFERROR(K2+0.04,"n.a.") -> 0.46833557
A3: =+RANDBETWEEN(Apoyo!$P$2,Apoyo!$P$3) -> 45952 | B3: {=+INDEX(Apoyo!$B$2:$B$10,RANDBETWEEN(1,9))} -> Puente Piedra-Ventanilla | C3: NNA | D3: {=+IF(OR($B3=Apoyo!$B$2,$B3=Apoyo!$B$6),"Lima",IF($B3=Apoyo!$B$10,INDEX(Apoyo!$D$2:$D$19,RANDBETWEEN(1,18)),IF(OR($B3<>Apoyo!$B$10,$B3<>Apoyo!$B$2,$B3<>Apoyo!$B$6),B3,0)))} -> Lima | E3: Femenino | F3: =+IF(C3="Mujer",RANDBETWEEN(18,65),RANDBETWEEN(12,17)) -> 12 | G3: Completa | H3: =+IF($G3<>"Completa",IF($G3<>"Discapacidad",0,RANDBETWEEN(0,1)),RANDBETWEEN(0,1)) -> 0 | I3: =+IF($G3<>"Completa",IF($G3<>"Discapacidad",0,RANDBETWEEN(0,1)),RANDBETWEEN(0,1)) -> 0 | J3: =+IF(OR(H3=1,I3=1),RANDBETWEEN(0,1),0) -> 0 | K3: =IF(G3<>"Completa","n.a.",RAND()) -> 0.16810298 | L3: =+IFERROR(K3+0.05,"n.a.") -> 0.21810298
A4: =+RANDBETWEEN(Apoyo!$P$2,Apoyo!$P$3) -> 45948 | B4: {=+INDEX(Apoyo!$B$2:$B$10,RANDBETWEEN(1,9))} -> Huánuco | C4: NNA | D4: {=+IF(OR($B4=Apoyo!$B$2,$B4=Apoyo!$B$6),"Lima",IF($B4=Apoyo!$B$10,INDEX(Apoyo!$D$2:$D$19,RANDBETWEEN(1,18)),IF(OR($B4<>Apoyo!$B$10,$B4<>Apoyo!$B$2,$B4<>Apoyo!$B$6),B4,0)))} -> Huánuco | E4: Masculino | F4: =+IF(C4="Mujer",RANDBETWEEN(18,65),RANDBETWEEN(12,17)) -> 16 | G4: Completa | H4: =+IF($G4<>"Completa",IF($G4<>"Discapacidad",0,RANDBETWEEN(0,1)),RANDBETWEEN(0,1)) -> 0 | I4: =+IF($G4<>"Completa",IF($G4<>"Discapacidad",0,RANDBETWEEN(0,1)),RANDBETWEEN(0,1)) -> 0 | J4: =+IF(OR(H4=1,I4=1),RANDBETWEEN(0,1),0) -> 0 | K4: =IF(G4<>"Completa","n.a.",RAND()) -> 0.82331395 | L4: =+IFERROR(K4+0.03,"n.a.") -> 0.85331395
A5: =+RANDBETWEEN(Apoyo!$P$2,Apoyo!$P$3) -> 45959 | B5: {=+INDEX(Apoyo!$B$2:$B$10,RANDBETWEEN(1,9))} -> Resto del Perú | C5: Mujer | D5: {=+IF(OR($B5=Apoyo!$B$2,$B5=Apoyo!$B$6),"Lima",IF($B5=Apoyo!$B$10,INDEX(Apoyo!$D$2:$D$19,RANDBETWEEN(1,18)),IF(OR($B5<>Apoyo!$B$10,$B5<>Apoyo!$B$2,$B5<>Apoyo!$B$6),B5,0)))} -> Amazonas | E5: =+IF(C5="Mujer","Femenino",2) -> Femenino | F5: =+IF(C5="Mujer",RANDBETWEEN(18,65),RANDBETWEEN(12,17)) -> 38 | G5: Completa | H5: =+IF($G5<>"Completa",IF($G5<>"Discapacidad",0,RANDBETWEEN(0,1)),RANDBETWEEN(0,1)) -> 0 | I5: =+IF($G5<>"Completa",IF($G5<>"Discapacidad",0,RANDBETWEEN(0,1)),RANDBETWEEN(0,1)) -> 0 | J5: =+IF(OR(H5=1,I5=1),RANDBETWEEN(0,1),0) -> 0 | K5: =IF(G5<>"Completa","n.a.",RAND()) -> 0.92488921 | L5: =+IFERROR(K5+0.03,"n.a.") -> 0.95488921
A6: =+RANDBETWEEN(Apoyo!$P$2,Apoyo!$P$3) -> 45950 | B6: {=+INDEX(Apoyo!$B$2:$B$10,RANDBETWEEN(1,9))} -> Resto del Perú | C6: Mujer | D6: {=+IF(OR($B6=Apoyo!$B$2,$B6=Apoyo!$B$6),"Lima",IF($B6=Apoyo!$B$10,INDEX(Apoyo!$D$2:$D$19,RANDBETWEEN(1,18)),IF(OR($B6<>Apoyo!$B$10,$B6<>Apoyo!$B$2,$B6<>Apoyo!$B$6),B6,0)))} -> Pasco | E6: =+IF(C6="Mujer","Femenino",2) -> Femenino | F6: =+IF(C6="Mujer",RANDBETWEEN(18,65),RANDBETWEEN(12,17)) -> 38 | G6: Completa | H6: =+IF($G6<>"Completa",IF($G6<>"Discapacidad",0,RANDBETWEEN(0,1)),RANDBETWEEN(0,1)) -> 0 | I6: =+IF($G6<>"Completa",IF($G6<>"Discapacidad",0,RANDBETWEEN(0,1)),RANDBETWEEN(0,1)) -> 0 | J6: =+IF(OR(H6=1,I6=1),RANDBETWEEN(0,1),0) -> 0 | K6: =IF(G6<>"Completa","n.a.",RAND()) -> 0.38412841 | L6: =+IFERROR(K6+0.04,"n.a.") -> 0.42412841
A7: =+RANDBETWEEN(Apoyo!$P$2,Apoyo!$P$3) -> 45956 | B7: {=+INDEX(Apoyo!$B$2:$B$10,RANDBETWEEN(1,9))} -> Lima Norte | C7: NNA | D7: {=+IF(OR($B7=Apoyo!$B$2,$B7=Apoyo!$B$6),"Lima",IF($B7=Apoyo!$B$10,INDEX(Apoyo!$D$2:$D$19,RANDBETWEEN(1,18)),IF(OR($B7<>Apoyo!$B$10,$B7<>Apoyo!$B$2,$B7<>Apoyo!$B$6),B7,0)))} -> Lima | E7: Masculino | F7: =+IF(C7="Mujer",RANDBETWEEN(18,65),RANDBETWEEN(12,17)) -> 15 | G7: Completa | H7: =+IF($G7<>"Completa",IF($G7<>"Discapacidad",0,RANDBETWEEN(0,1)),RANDBETWEEN(0,1)) -> 0 | I7: =+IF($G7<>"Completa",IF($G7<>"Discapacidad",0,RANDBETWEEN(0,1)),RANDBETWEEN(0,1)) -> 0 | J7: =+IF(OR(H7=1,I7=1),RANDBETWEEN(0,1),0) -> 0 | K7: =IF(G7<>"Completa","n.a.",RAND()) -> 0.9677802 | L7: =+IFERROR(K7+0.06,"n.a.") -> 1.0277802
A8: =+RANDBETWEEN(Apoyo!$P$2,Apoyo!$P$3) -> 45959 | B8: {=+INDEX(Apoyo!$B$2:$B$10,RANDBETWEEN(1,9))} -> Puente Piedra-Ventanilla | C8: NNA | D8: {=+IF(OR($B8=Apoyo!$B$2,$B8=Apoyo!$B$6),"Lima",IF($B8=Apoyo!$B$10,INDEX(Apoyo!$D$2:$D$19,RANDBETWEEN(1,18)),IF(OR($B8<>Apoyo!$B$10,$B8<>Apoyo!$B$2,$B8<>Apoyo!$B$6),B8,0)))} -> Lima | E8: Femenino | F8: =+IF(C8="Mujer",RANDBETWEEN(18,65),RANDBETWEEN(12,17)) -> 15 | G8: Completa | H8: =+IF($G8<>"Completa",IF($G8<>"Discapacidad",0,RANDBETWEEN(0,1)),RANDBETWEEN(0,1)) -> 0 | I8: =+IF($G8<>"Completa",IF($G8<>"Discapacidad",0,RANDBETWEEN(0,1)),RANDBETWEEN(0,1)) -> 0 | J8: =+IF(OR(H8=1,I8=1),RANDBETWEEN(0,1),0) -> 0 | K8: =IF(G8<>"Completa","n.a.",RAND()) -> 0.0017072984 | L8: =+IFERROR(K8+0.03,"n.a.") -> 0.031707298
A9: =+RANDBETWEEN(Apoyo!$P$2,Apoyo!$P$3) -> 45958 | B9: {=+INDEX(Apoyo!$B$2:$B$10,RANDBETWEEN(1,9))} -> Ucayali | C9: Mujer | D9: {=+IF(OR($B9=Apoyo!$B$2,$B9=Apoyo!$B$6),"Lima",IF($B9=Apoyo!$B$10,INDEX(Apoyo!$D$2:$D$19,RANDBETWEEN(1,18)),IF(OR($B9<>Apoyo!$B$10,$B9<>Apoyo!$B$2,$B9<>Apoyo!$B$6),B9,0)))} -> Ucayali | E9: =+IF(C9="Mujer","Femenino",2) -> Femenino | F9: =+IF(C9="Mujer",RANDBETWEEN(18,65),RANDBETWEEN(12,17)) -> 41 | G9: Completa | H9: =+IF($G9<>"Completa",IF($G9<>"Discapacidad",0,RANDBETWEEN(0,1)),RANDBETWEEN(0,1)) -> 0 | I9: =+IF($G9<>"Completa",IF($G9<>"Discapacidad",0,RANDBETWEEN(0,1)),RANDBETWEEN(0,1)) -> 1 | J9: =+IF(OR(H9=1,I9=1),RANDBETWEEN(0,1),0) -> 0 | K9: =IF(G9<>"Completa","n.a.",RAND()) -> 0.69673941 | L9: =+IFERROR(K9+0.05,"n.a.") -> 0.74673941
A10: =+RANDBETWEEN(Apoyo!$P$2,Apoyo!$P$3) -> 45955 | B10: {=+INDEX(Apoyo!$B$2:$B$10,RANDBETWEEN(1,9))} -> Loreto | C10: NNA | D10: {=+IF(OR($B10=Apoyo!$B$2,$B10=Apoyo!$B$6),"Lima",IF($B10=Apoyo!$B$10,INDEX(Apoyo!$D$2:$D$19,RANDBETWEEN(1,18)),IF(OR($B10<>Apoyo!$B$10,$B10<>Apoyo!$B$2,$B10<>Apoyo!$B$6),B10,0)))} -> Loreto | E10: Masculino | F10: =+IF(C10="Mujer",RANDBETWEEN(18,65),RANDBETWEEN(12,17)) -> 12 | G10: =+CHOOSE(RANDBETWEEN(1,5),Apoyo!$E$3,Apoyo!$E$4,Apoyo!$E$5,Apoyo!$E$6,Apoyo!$E$7) -> Rechazada | H10: =+IF($G10<>"Completa",IF($G10<>"Discapacidad",0,RANDBETWEEN(0,1)),RANDBETWEEN(0,1)) -> 0 | I10: =+IF($G10<>"Completa",IF($G10<>"Discapacidad",0,RANDBETWEEN(0,1)),RANDBETWEEN(0,1)) -> 0 | J10: =+IF(OR(H10=1,I10=1),RANDBETWEEN(0,1),0) -> 0 | K10: =IF(G10<>"Completa","n.a.",RAND()) -> n.a. | L10: =+IFERROR(K10+0.04,"n.a.") -> n.a.
A11: =+RANDBETWEEN(Apoyo!$P$2,Apoyo!$P$3) -> 45954 | B11: {=+INDEX(Apoyo!$B$2:$B$10,RANDBETWEEN(1,9))} -> Huánuco | C11: Mujer | D11: {=+IF(OR($B11=Apoyo!$B$2,$B11=Apoyo!$B$6),"Lima",IF($B11=Apoyo!$B$10,INDEX(Apoyo!$D$2:$D$19,RANDBETWEEN(1,18)),IF(OR($B11<>Apoyo!$B$10,$B11<>Apoyo!$B$2,$B11<>Apoyo!$B$6),B11,0)))} -> Huánuco | E11: =+IF(C11="Mujer","Femenino",2) -> Femenino | F11: =+IF(C11="Mujer",RANDBETWEEN(18,65),RANDBETWEEN(12,17)) -> 24 | G11: Completa | H11: =+IF($G11<>"Completa",IF($G11<>"Discapacidad",0,RANDBETWEEN(0,1)),RANDBETWEEN(0,1)) -> 0 | I11: =+IF($G11<>"Completa",IF($G11<>"Discapacidad",0,RANDBETWEEN(0,1)),RANDBETWEEN(0,1)) -> 0 | J11: =+IF(OR(H11=1,I11=1),RANDBETWEEN(0,1),0) -> 0 | K11: =IF(G11<>"Completa","n.a.",RAND()) -> 0.66952187 | L11: =+IFERROR(K11+0.05,"n.a.") -> 0.71952187
A12: =+RANDBETWEEN(Apoyo!$P$2,Apoyo!$P$3) -> 45952 | B12: {=+INDEX(Apoyo!$B$2:$B$10,RANDBETWEEN(1,9))} -> Apurímac | C12: Mujer | D12: {=+IF(OR($B12=Apoyo!$B$2,$B12=Apoyo!$B$6),"Lima",IF($B12=Apoyo!$B$10,INDEX(Apoyo!$D$2:$D$19,RANDBETWEEN(1,18)),IF(OR($B12<>Apoyo!$B$10,$B12<>Apoyo!$B$2,$B12<>Apoyo!$B$6),B12,0)))} -> Apurímac | E12: =+IF(C12="Mujer","Femenino",2) -> Femenino | F12: =+IF(C12="Mujer",RANDBETWEEN(18,65),RANDBETWEEN(12,17)) -> 58 | G12: Completa | H12: =+IF($G12<>"Completa",IF($G12<>"Discapacidad",0,RANDBETWEEN(0,1)),RANDBETWEEN(0,1)) -> 0 | I12: =+IF($G12<>"Completa",IF($G12<>"Discapacidad",0,RANDBETWEEN(0,1)),RANDBETWEEN(0,1)) -> 1 | J12: =+IF(OR(H12=1,I12=1),RANDBETWEEN(0,1),0) -> 1 | K12: =IF(G12<>"Completa","n.a.",RAND()) -> 0.91037046 | L12: =+IFERROR(K12+0.03,"n.a.") -> 0.94037046
A13: =+RANDBETWEEN(Apoyo!$P$2,Apoyo!$P$3) -> 45953 | B13: {=+INDEX(Apoyo!$B$2:$B$10,RANDBETWEEN(1,9))} -> Lima Norte | C13: NNA | D13: {=+IF(OR($B13=Apoyo!$B$2,$B13=Apoyo!$B$6),"Lima",IF($B13=Apoyo!$B$10,INDEX(Apoyo!$D$2:$D$19,RANDBETWEEN(1,18)),IF(OR($B13<>Apoyo!$B$10,$B13<>Apoyo!$B$2,$B13<>Apoyo!$B$6),B13,0)))} -> Lima | E13: Femenino | F13: =+IF(C13="Mujer",RANDBETWEEN(18,65),RANDBETWEEN(12,17)) -> 13 | G13: Completa | H13: =+IF($G13<>"Completa",IF($G13<>"Discapacidad",0,RANDBETWEEN(0,1)),RANDBETWEEN(0,1)) -> 1 | I13: =+IF($G13<>"Completa",IF($G13<>"Discapacidad",0,RANDBETWEEN(0,1)),RANDBETWEEN(0,1)) -> 0 | J13: =+IF(OR(H13=1,I13=1),RANDBETWEEN(0,1),0) -> 0 | K13: =IF(G13<>"Completa","n.a.",RAND()) -> 0.13749333 | L13: =+IFERROR(K13+0.03,"n.a.") -> 0.16749333
A14: =+RANDBETWEEN(Apoyo!$P$2,Apoyo!$P$3) -> 45955 | B14: {=+INDEX(Apoyo!$B$2:$B$10,RANDBETWEEN(1,9))} -> Ucayali | C14: NNA | D14: {=+IF(OR($B14=Apoyo!$B$2,$B14=Apoyo!$B$6),"Lima",IF($B14=Apoyo!$B$10,INDEX(Apoyo!$D$2:$D$19,RANDBETWEEN(1,18)),IF(OR($B14<>Apoyo!$B$10,$B14<>Apoyo!$B$2,$B14<>Apoyo!$B$6),B14,0)))} -> Ucayali | E14: Masculino | F14: =+IF(C14="Mujer",RANDBETWEEN(18,65),RANDBETWEEN(12,17)) -> 16 | G14: =+CHOOSE(RANDBETWEEN(1,5),Apoyo!$E$3,Apoyo!$E$4,Apoyo!$E$5,Apoyo!$E$6,Apoyo!$E$7) -> Ausente | H14: =+IF($G14<>"Completa",IF($G14<>"Discapacidad",0,RANDBETWEEN(0,1)),RANDBETWEEN(0,1)) -> 0 | I14: =+IF($G14<>"Completa",IF($G14<>"Discapacidad",0,RANDBETWEEN(0,1)),RANDBETWEEN(0,1)) -> 0 | J14: =+IF(OR(H14=1,I14=1),RANDBETWEEN(0,1),0) -> 0 | K14: =IF(G14<>"Completa","n.a.",RAND()) -> n.a. | L14: =+IFERROR(K14+0.04,"n.a.") -> n.a.
A15: =+RANDBETWEEN(Apoyo!$P$2,Apoyo!$P$3) -> 45959 | B15: {=+INDEX(Apoyo!$B$2:$B$10,RANDBETWEEN(1,9))} -> Puente Piedra-Ventanilla | C15: Mujer | D15: {=+IF(OR($B15=Apoyo!$B$2,$B15=Apoyo!$B$6),"Lima",IF($B15=Apoyo!$B$10,INDEX(Apoyo!$D$2:$D$19,RANDBETWEEN(1,18)),IF(OR($B15<>Apoyo!$B$10,$B15<>Apoyo!$B$2,$B15<>Apoyo!$B$6),B15,0)))} -> Lima | E15: =+IF(C15="Mujer","Femenino",2) -> Femenino | F15: =+IF(C15="Mujer",RANDBETWEEN(18,65),RANDBETWEEN(12,17)) -> 60 | G15: Completa | H15: =+IF($G15<>"Completa",IF($G15<>"Discapacidad",0,RANDBETWEEN(0,1)),RANDBETWEEN(0,1)) -> 1 | I15: =+IF($G15<>"Completa",IF($G15<>"Discapacidad",0,RANDBETWEEN(0,1)),RANDBETWEEN(0,1)) -> 1 | J15: =+IF(OR(H15=1,I15=1),RANDBETWEEN(0,1),0) -> 1 | K15: =IF(G15<>"Completa","n.a.",RAND()) -> 0.46152683 | L15: =+IFERROR(K15+0.05,"n.a.") -> 0.51152683
A16: =+RANDBETWEEN(Apoyo!$P$2,Apoyo!$P$3) -> 45953 | B16: {=+INDEX(Apoyo!$B$2:$B$10,RANDBETWEEN(1,9))} -> Ucayali | C16: Mujer | D16: {=+IF(OR($B16=Apoyo!$B$2,$B16=Apoyo!$B$6),"Lima",IF($B16=Apoyo!$B$10,INDEX(Apoyo!$D$2:$D$19,RANDBETWEEN(1,18)),IF(OR($B16<>Apoyo!$B$10,$B16<>Apoyo!$B$2,$B16<>Apoyo!$B$6),B16,0)))} -> Ucayali | E16: =+IF(C16="Mujer","Femenino",2) -> Femenino | F16: =+IF(C16="Mujer",RANDBETWEEN(18,65),RANDBETWEEN(12,17)) -> 44 | G16: Completa | H16: =+IF($G16<>"Completa",IF($G16<>"Discapacidad",0,RANDBETWEEN(0,1)),RANDBETWEEN(0,1)) -> 1 | I16: =+IF($G16<>"Completa",IF($G16<>"Discapacidad",0,RANDBETWEEN(0,1)),RANDBETWEEN(0,1)) -> 1 | J16: =+IF(OR(H16=1,I16=1),RANDBETWEEN(0,1),0) -> 0 | K16: =IF(G16<>"Completa","n.a.",RAND()) -> 0.058386197 | L16: =+IFERROR(K16+0.03,"n.a.") -> 0.088386197
A17: =+RANDBETWEEN(Apoyo!$P$2,Apoyo!$P$3) -> 45955 | B17: {=+INDEX(Apoyo!$B$2:$B$10,RANDBETWEEN(1,9))} -> Lima Norte | C17: NNA | D17: {=+IF(OR($B17=Apoyo!$B$2,$B17=Apoyo!$B$6),"Lima",IF($B17=Apoyo!$B$10,INDEX(Apoyo!$D$2:$D$19,RANDBETWEEN(1,18)),IF(OR($B17<>Apoyo!$B$10,$B17<>Apoyo!$B$2,$B17<>Apoyo!$B$6),B17,0)))} -> Lima | E17: Masculino | F17: =+IF(C17="Mujer",RANDBETWEEN(18,65),RANDBETWEEN(12,17)) -> 12 | G17: Completa | H17: =+IF($G17<>"Completa",IF($G17<>"Discapacidad",0,RANDBETWEEN(0,1)),RANDBETWEEN(0,1)) -> 0 | I17: =+IF($G17<>"Completa",IF($G17<>"Discapacidad",0,RANDBETWEEN(0,1)),RANDBETWEEN(0,1)) -> 1 | J17: =+IF(OR(H17=1,I17=1),RANDBETWEEN(0,1),0) -> 1 | K17: =IF(G17<>"Completa","n.a.",RAND()) -> 0.65823745 | L17: =+IFERROR(K17+0.03,"n.a.") -> 0.68823745
A18: =+RANDBETWEEN(Apoyo!$P$2,Apoyo!$P$3) -> 45953 | B18: {=+INDEX(Apoyo!$B$2:$B$10,RANDBETWEEN(1,9))} -> Resto del Perú | C18: NNA | D18: {=+IF(OR($B18=Apoyo!$B$2,$B18=Apoyo!$B$6),"Lima",IF($B18=Apoyo!$B$10,INDEX(Apoyo!$D$2:$D$19,RANDBETWEEN(1,18)),IF(OR($B18<>Apoyo!$B$10,$B18<>Apoyo!$B$2,$B18<>Apoyo!$B$6),B18,0)))} -> Piura | E18: Femenino | F18: =+IF(C18="Mujer",RANDBETWEEN(18,65),RANDBETWEEN(12,17)) -> 12 | G18: Completa | H18: =+IF($G18<>"Completa",IF($G18<>"Discapacidad",0,RANDBETWEEN(0,1)),RANDBETWEEN(0,1)) -> 0 | I18: =+IF($G18<>"Completa",IF($G18<>"Discapacidad",0,RANDBETWEEN(0,1)),RANDBETWEEN(0,1)) -> 1 | J18: =+IF(OR(H18=1,I18=1),RANDBETWEEN(0,1),0) -> 1 | K18: =IF(G18<>"Completa","n.a.",RAND()) -> 0.014745248 | L18: =+IFERROR(K18+0.04,"n.a.") -> 0.054745248
A19: =+RANDBETWEEN(Apoyo!$P$2,Apoyo!$P$3) -> 45945 | B19: {=+INDEX(Apoyo!$B$2:$B$10,RANDBETWEEN(1,9))} -> Apurímac | C19: Mujer | D19: {=+IF(OR($B19=Apoyo!$B$2,$B19=Apoyo!$B$6),"Lima",IF($B19=Apoyo!$B$10,INDEX(Apoyo!$D$2:$D$19,RANDBETWEEN(1,18)),IF(OR($B19<>Apoyo!$B$10,$B19<>Apoyo!$B$2,$B19<>Apoyo!$B$6),B19,0)))} -> Apurímac | E19: =+IF(C19="Mujer","Femenino",2) -> Femenino | F19: =+IF(C19="Mujer",RANDBETWEEN(18,65),RANDBETWEEN(12,17)) -> 35 | G19: =+CHOOSE(RANDBETWEEN(1,5),Apoyo!$E$3,Apoyo!$E$4,Apoyo!$E$5,Apoyo!$E$6,Apoyo!$E$7) -> Otro | H19: =+IF($G19<>"Completa",IF($G19<>"Discapacidad",0,RANDBETWEEN(0,1)),RANDBETWEEN(0,1)) -> 0 | I19: =+IF($G19<>"Completa",IF($G19<>"Discapacidad",0,RANDBETWEEN(0,1)),RANDBETWEEN(0,1)) -> 0 | J19: =+IF(OR(H19=1,I19=1),RANDBETWEEN(0,1),0) -> 0 | K19: =IF(G19<>"Completa","n.a.",RAND()) -> n.a. | L19: =+IFERROR(K19+0.06,"n.a.") -> n.a.
A20: =+RANDBETWEEN(Apoyo!$P$2,Apoyo!$P$3) -> 45947 | B20: {=+INDEX(Apoyo!$B$2:$B$10,RANDBETWEEN(1,9))} -> Ucayali | C20: NNA | D20: {=+IF(OR($B20=Apoyo!$B$2,$B20=Apoyo!$B$6),"Lima",IF($B20=Apoyo!$B$10,INDEX(Apoyo!$D$2:$D$19,RANDBETWEEN(1,18)),IF(OR($B20<>Apoyo!$B$10,$B20<>Apoyo!$B$2,$B20<>Apoyo!$B$6),B20,0)))} -> Ucayali | E20: Masculino | F20: =+IF(C20="Mujer",RANDBETWEEN(18,65),RANDBETWEEN(12,17)) -> 17 | G20: =+CHOOSE(RANDBETWEEN(1,5),Apoyo!$E$3,Apoyo!$E$4,Apoyo!$E$5,Apoyo!$E$6,Apoyo!$E$7) -> Aplazada | H20: =+IF($G20<>"Completa",IF($G20<>"Discapacidad",0,RANDBETWEEN(0,1)),RANDBETWEEN(0,1)) -> 0 | I20: =+IF($G20<>"Completa",IF($G20<>"Discapacidad",0,RANDBETWEEN(0,1)),RANDBETWEEN(0,1)) -> 0 | J20: =+IF(OR(H20=1,I20=1),RANDBETWEEN(0,1),0) -> 0 | K20: =IF(G20<>"Completa","n.a.",RAND()) -> n.a. | L20: =+IFERROR(K20+0.03,"n.a.") -> n.a.
A21: =+RANDBETWEEN(Apoyo!$P$2,Apoyo!$P$3) -> 45951 | B21: {=+INDEX(Apoyo!$B$2:$B$10,RANDBETWEEN(1,9))} -> Loreto | C21: Mujer | D21: {=+IF(OR($B21=Apoyo!$B$2,$B21=Apoyo!$B$6),"Lima",IF($B21=Apoyo!$B$10,INDEX(Apoyo!$D$2:$D$19,RANDBETWEEN(1,18)),IF(OR($B21<>Apoyo!$B$10,$B21<>Apoyo!$B$2,$B21<>Apoyo!$B$6),B21,0)))} -> Loreto | E21: =+IF(C21="Mujer","Femenino",2) -> Femenino | F21: =+IF(C21="Mujer",RANDBETWEEN(18,65),RANDBETWEEN(12,17)) -> 45 | G21: Completa | H21: =+IF($G21<>"Completa",IF($G21<>"Discapacidad",0,RANDBETWEEN(0,1)),RANDBETWEEN(0,1)) -> 1 | I21: =+IF($G21<>"Completa",IF($G21<>"Discapacidad",0,RANDBETWEEN(0,1)),RANDBETWEEN(0,1)) -> 1 | J21: =+IF(OR(H21=1,I21=1),RANDBETWEEN(0,1),0) -> 0 | K21: =IF(G21<>"Completa","n.a.",RAND()) -> 0.38820747 | L21: =+IFERROR(K21+0.05,"n.a.") -> 0.43820747
A22: =+RANDBETWEEN(Apoyo!$P$2,Apoyo!$P$3) -> 45952 | B22: {=+INDEX(Apoyo!$B$2:$B$10,RANDBETWEEN(1,9))} -> Loreto | C22: Mujer | D22: {=+IF(OR($B22=Apoyo!$B$2,$B22=Apoyo!$B$6),"Lima",IF($B22=Apoyo!$B$10,INDEX(Apoyo!$D$2:$D$19,RANDBETWEEN(1,18)),IF(OR($B22<>Apoyo!$B$10,$B22<>Apoyo!$B$2,$B22<>Apoyo!$B$6),B22,0)))} -> Loreto | E22: =+IF(C22="Mujer","Femenino",2) -> Femenino | F22: =+IF(C22="Mujer",RANDBETWEEN(18,65),RANDBETWEEN(12,17)) -> 38 | G22: Completa | H22: =+IF($G22<>"Completa",IF($G22<>"Discapacidad",0,RANDBETWEEN(0,1)),RANDBETWEEN(0,1)) -> 1 | I22: =+IF($G22<>"Completa",IF($G22<>"Discapacidad",0,RANDBETWEEN(0,1)),RANDBETWEEN(0,1)) -> 0 | J22: =+IF(OR(H22=1,I22=1),RANDBETWEEN(0,1),0) -> 1 | K22: =IF(G22<>"Completa","n.a.",RAND()) -> 0.43546679 | L22: =+IFERROR(K22+0.04,"n.a.") -> 0.47546679
A23: =+RANDBETWEEN(Apoyo!$P$2,Apoyo!$P$3) -> 45951 | B23: {=+INDEX(Apoyo!$B$2:$B$10,RANDBETWEEN(1,9))} -> Apurímac | C23: NNA | D23: {=+IF(OR($B23=Apoyo!$B$2,$B23=Apoyo!$B$6),"Lima",IF($B23=Apoyo!$B$10,INDEX(Apoyo!$D$2:$D$19,RANDBETWEEN(1,18)),IF(OR($B23<>Apoyo!$B$10,$B23<>Apoyo!$B$2,$B23<>Apoyo!$B$6),B23,0)))} -> Apurímac | E23: Femenino | F23: =+IF(C23="Mujer",RANDBETWEEN(18,65),RANDBETWEEN(12,17)) -> 17 | G23: Completa | H23: =+IF($G23<>"Completa",IF($G23<>"Discapacidad",0,RANDBETWEEN(0,1)),RANDBETWEEN(0,1)) -> 1 | I23: =+IF($G23<>"Completa",IF($G23<>"Discapacidad",0,RANDBETWEEN(0,1)),RANDBETWEEN(0,1)) -> 0 | J23: =+IF(OR(H23=1,I23=1),RANDBETWEEN(0,1),0) -> 1 | K23: =IF(G23<>"Completa","n.a.",RAND()) -> 0.50243689 | L23: =+IFERROR(K23+0.05,"n.a.") -> 0.55243689
A24: =+RANDBETWEEN(Apoyo!$P$2,Apoyo!$P$3) -> 45957 | B24: {=+INDEX(Apoyo!$B$2:$B$10,RANDBETWEEN(1,9))} -> Puente Piedra-Ventanilla | C24: NNA | D24: {=+IF(OR($B24=Apoyo!$B$2,$B24=Apoyo!$B$6),"Lima",IF($B24=Apoyo!$B$10,INDEX(Apoyo!$D$2:$D$19,RANDBETWEEN(1,18)),IF(OR($B24<>Apoyo!$B$10,$B24<>Apoyo!$B$2,$B24<>Apoyo!$B$6),B24,0)))} -> Lima | E24: Masculino | F24: =+IF(C24="Mujer",RANDBETWEEN(18,65),RANDBETWEEN(12,17)) -> 14 | G24: Completa | H24: =+IF($G24<>"Completa",IF($G24<>"Discapacidad",0,RANDBETWEEN(0,1)),RANDBETWEEN(0,1)) -> 1 | I24: =+IF($G24<>"Completa",IF($G24<>"Discapacidad",0,RANDBETWEEN(0,1)),RANDBETWEEN(0,1)) -> 0 | J24: =+IF(OR(H24=1,I24=1),RANDBETWEEN(0,1),0) -> 0 | K24: =IF(G24<>"Completa","n.a.",RAND()) -> 0.86966586 | L24: =+IFERROR(K24+0.03,"n.a.") -> 0.89966586
A25: =+RANDBETWEEN(Apoyo!$P$2,Apoyo!$P$3) -> 45950 | B25: {=+INDEX(Apoyo!$B$2:$B$10,RANDBETWEEN(1,9))} -> Apurímac | C25: Mujer | D25: {=+IF(OR($B25=Apoyo!$B$2,$B25=Apoyo!$B$6),"Lima",IF($B25=Apoyo!$B$10,INDEX(Apoyo!$D$2:$D$19,RANDBETWEEN(1,18)),IF(OR($B25<>Apoyo!$B$10,$B25<>Apoyo!$B$2,$B25<>Apoyo!$B$6),B25,0)))} -> Apurímac | E25: =+IF(C25="Mujer","Femenino",2) -> Femenino | F25: =+IF(C25="Mujer",RANDBETWEEN(18,65),RANDBETWEEN(12,17)) -> 39 | G25: Completa | H25: =+IF($G25<>"Completa",IF($G25<>"Discapacidad",0,RANDBETWEEN(0,1)),RANDBETWEEN(0,1)) -> 1 | I25: =+IF($G25<>"Completa",IF($G25<>"Discapacidad",0,RANDBETWEEN(0,1)),RANDBETWEEN(0,1)) -> 0 | J25: =+IF(OR(H25=1,I25=1),RANDBETWEEN(0,1),0) -> 0 | K25: =IF(G25<>"Completa","n.a.",RAND()) -> 0.34439114 | L25: =+IFERROR(K25+0.03,"n.a.") -> 0.37439114
A26: =+RANDBETWEEN(Apoyo!$P$2,Apoyo!$P$3) -> 45945 | B26: {=+INDEX(Apoyo!$B$2:$B$10,RANDBETWEEN(1,9))} -> Huánuco | C26: Mujer | D26: {=+IF(OR($B26=Apoyo!$B$2,$B26=Apoyo!$B$6),"Lima",IF($B26=Apoyo!$B$10,INDEX(Apoyo!$D$2:$D$19,RANDBETWEEN(1,18)),IF(OR($B26<>Apoyo!$B$10,$B26<>Apoyo!$B$2,$B26<>Apoyo!$B$6),B26,0)))} -> Huánuco | E26: =+IF(C26="Mujer","Femenino",2) -> Femenino | F26: =+IF(C26="Mujer",RANDBETWEEN(18,65),RANDBETWEEN(12,17)) -> 60 | G26: Completa | H26: =+IF($G26<>"Completa",IF($G26<>"Discapacidad",0,RANDBETWEEN(0,1)),RANDBETWEEN(0,1)) -> 0 | I26: =+IF($G26<>"Completa",IF($G26<>"Discapacidad",0,RANDBETWEEN(0,1)),RANDBETWEEN(0,1)) -> 0 | J26: =+IF(OR(H26=1,I26=1),RANDBETWEEN(0,1),0) -> 0 | K26: =IF(G26<>"Completa","n.a.",RAND()) -> 0.40942538 | L26: =+IFERROR(K26+0.04,"n.a.") -> 0.44942538
A27: =+RANDBETWEEN(Apoyo!$P$2,Apoyo!$P$3) -> 45958 | B27: {=+INDEX(Apoyo!$B$2:$B$10,RANDBETWEEN(1,9))} -> Huánuco | C27: NNA | D27: {=+IF(OR($B27=Apoyo!$B$2,$B27=Apoyo!$B$6),"Lima",IF($B27=Apoyo!$B$10,INDEX(Apoyo!$D$2:$D$19,RANDBETWEEN(1,18)),IF(OR($B27<>Apoyo!$B$10,$B27<>Apoyo!$B$2,$B27<>Apoyo!$B$6),B27,0)))} -> Huánuco | E27: Masculino | F27: =+IF(C27="Mujer",RANDBETWEEN(18,65),RANDBETWEEN(12,17)) -> 14 | G27: Completa | H27: =+IF($G27<>"Completa",IF($G27<>"Discapacidad",0,RANDBETWEEN(0,1)),RANDBETWEEN(0,1)) -> 1 | I27: =+IF($G27<>"Completa",IF($G27<>"Discapacidad",0,RANDBETWEEN(0,1)),RANDBETWEEN(0,1)) -> 0 | J27: =+IF(OR(H27=1,I27=1),RANDBETWEEN(0,1),0) -> 0 | K27: =IF(G27<>"Completa","n.a.",RAND()) -> 0.93626736 | L27: =+IFERROR(K27+0.05,"n.a.") -> 0.98626736
A28: =+RANDBETWEEN(Apoyo!$P$2,Apoyo!$P$3) -> 45957 | B28: {=+INDEX(Apoyo!$B$2:$B$10,RANDBETWEEN(1,9))} -> Loreto | C28: NNA | D28: {=+IF(OR($B28=Apoyo!$B$2,$B28=Apoyo!$B$6),"Lima",IF($B28=Apoyo!$B$10,INDEX(Apoyo!$D$2:$D$19,RANDBETWEEN(1,18)),IF(OR($B28<>Apoyo!$B$10,$B28<>Apoyo!$B$2,$B28<>Apoyo!$B$6),B28,0)))} -> Loreto | E28: Femenino | F28: =+IF(C28="Mujer",RANDBETWEEN(18,65),RANDBETWEEN(12,17)) -> 16 | G28: Completa | H28: =+IF($G28<>"Completa",IF($G28<>"Discapacidad",0,RANDBETWEEN(0,1)),RANDBETWEEN(0,1)) -> 1 | I28: =+IF($G28<>"Completa",IF($G28<>"Discapacidad",0,RANDBETWEEN(0,1)),RANDBETWEEN(0,1)) -> 0 | J28: =+IF(OR(H28=1,I28=1),RANDBETWEEN(0,1),0) -> 1 | K28: =IF(G28<>"Completa","n.a.",RAND()) -> 0.57836763 | L28: =+IFERROR(K28+0.03,"n.a.") -> 0.60836763
A29: =+RANDBETWEEN(Apoyo!$P$2,Apoyo!$P$3) -> 45946 | B29: {=+INDEX(Apoyo!$B$2:$B$10,RANDBETWEEN(1,9))} -> Lima Norte | C29: Mujer | D29: {=+IF(OR($B29=Apoyo!$B$2,$B29=Apoyo!$B$6),"Lima",IF($B29=Apoyo!$B$10,INDEX(Apoyo!$D$2:$D$19,RANDBETWEEN(1,18)),IF(OR($B29<>Apoyo!$B$10,$B29<>Apoyo!$B$2,$B29<>Apoyo!$B$6),B29,0)))} -> Lima | E29: =+IF(C29="Mujer","Femenino",2) -> Femenino | F29: =+IF(C29="Mujer",RANDBETWEEN(18,65),RANDBETWEEN(12,17)) -> 60 | G29: Completa | H29: =+IF($G29<>"Completa",IF($G29<>"Discapacidad",0,RANDBETWEEN(0,1)),RANDBETWEEN(0,1)) -> 0 | I29: =+IF($G29<>"Completa",IF($G29<>"Discapacidad",0,RANDBETWEEN(0,1)),RANDBETWEEN(0,1)) -> 1 | J29: =+IF(OR(H29=1,I29=1),RANDBETWEEN(0,1),0) -> 0 | K29: =IF(G29<>"Completa","n.a.",RAND()) -> 0.88627068 | L29: =+IFERROR(K29+0.03,"n.a.") -> 0.91627068
A30: =+RANDBETWEEN(Apoyo!$P$2,Apoyo!$P$3) -> 45954 | B30: {=+INDEX(Apoyo!$B$2:$B$10,RANDBETWEEN(1,9))} -> Cajamarca | C30: NNA | D30: {=+IF(OR($B30=Apoyo!$B$2,$B30=Apoyo!$B$6),"Lima",IF($B30=Apoyo!$B$10,INDEX(Apoyo!$D$2:$D$19,RANDBETWEEN(1,18)),IF(OR($B30<>Apoyo!$B$10,$B30<>Apoyo!$B$2,$B30<>Apoyo!$B$6),B30,0)))} -> Cajamarca | E30: Masculino | F30: =+IF(C30="Mujer",RANDBETWEEN(18,65),RANDBETWEEN(12,17)) -> 12 | G30: Completa | H30: =+IF($G30<>"Completa",IF($G30<>"Discapacidad",0,RANDBETWEEN(0,1)),RANDBETWEEN(0,1)) -> 1 | I30: =+IF($G30<>"Completa",IF($G30<>"Discapacidad",0,RANDBETWEEN(0,1)),RANDBETWEEN(0,1)) -> 1 | J30: =+IF(OR(H30=1,I30=1),RANDBETWEEN(0,1),0) -> 0 | K30: =IF(G30<>"Completa","n.a.",RAND()) -> 0.084572315 | L30: =+IFERROR(K30+0.04,"n.a.") -> 0.12457232
A31: =+RANDBETWEEN(Apoyo!$P$2,Apoyo!$P$3) -> 45956 | B31: {=+INDEX(Apoyo!$B$2:$B$10,RANDBETWEEN(1,9))} -> Ucayali | C31: Mujer | D31: {=+IF(OR($B31=Apoyo!$B$2,$B31=Apoyo!$B$6),"Lima",IF($B31=Apoyo!$B$10,INDEX(Apoyo!$D$2:$D$19,RANDBETWEEN(1,18)),IF(OR($B31<>Apoyo!$B$10,$B31<>Apoyo!$B$2,$B31<>Apoyo!$B$6),B31,0)))} -> Ucayali | E31: =+IF(C31="Mujer","Femenino",2) -> Femenino | F31: =+IF(C31="Mujer",RANDBETWEEN(18,65),RANDBETWEEN(12,17)) -> 52 | G31: Completa | H31: =+IF($G31<>"Completa",IF($G31<>"Discapacidad",0,RANDBETWEEN(0,1)),RANDBETWEEN(0,1)) -> 1 | I31: =+IF($G31<>"Completa",IF($G31<>"Discapacidad",0,RANDBETWEEN(0,1)),RANDBETWEEN(0,1)) -> 0 | J31: =+IF(OR(H31=1,I31=1),RANDBETWEEN(0,1),0) -> 0 | K31: =IF(G31<>"Completa","n.a.",RAND()) -> 0.22255807 | L31: =+IFERROR(K31+0.06,"n.a.") -> 0.28255807
A32: =+RANDBETWEEN(Apoyo!$P$2,Apoyo!$P$3) -> 45947 | B32: {=+INDEX(Apoyo!$B$2:$B$10,RANDBETWEEN(1,9))} -> Ucayali | C32: Mujer | D32: {=+IF(OR($B32=Apoyo!$B$2,$B32=Apoyo!$B$6),"Lima",IF($B32=Apoyo!$B$10,INDEX(Apoyo!$D$2:$D$19,RANDBETWEEN(1,18)),IF(OR($B32<>Apoyo!$B$10,$B32<>Apoyo!$B$2,$B32<>Apoyo!$B$6),B32,0)))} -> Ucayali | E32: =+IF(C32="Mujer","Femenino",2) -> Femenino | F32: =+IF(C32="Mujer",RANDBETWEEN(18,65),RANDBETWEEN(12,17)) -> 28 | G32: Completa | H32: =+IF($G32<>"Completa",IF($G32<>"Discapacidad",0,RANDBETWEEN(0,1)),RANDBETWEEN(0,1)) -> 0 | I32: =+IF($G32<>"Completa",IF($G32<>"Discapacidad",0,RANDBETWEEN(0,1)),RANDBETWEEN(0,1)) -> 0 | J32: =+IF(OR(H32=1,I32=1),RANDBETWEEN(0,1),0) -> 0 | K32: =IF(G32<>"Completa","n.a.",RAND()) -> 0.76681681 | L32: =+IFERROR(K32+0.03,"n.a.") -> 0.79681681
A33: =+RANDBETWEEN(Apoyo!$P$2,Apoyo!$P$3) -> 45946 | B33: {=+INDEX(Apoyo!$B$2:$B$10,RANDBETWEEN(1,9))} -> Resto del Perú | C33: NNA | D33: {=+IF(OR($B33=Apoyo!$B$2,$B33=Apoyo!$B$6),"Lima",IF($B33=Apoyo!$B$10,INDEX(Apoyo!$D$2:$D$19,RANDBETWEEN(1,18)),IF(OR($B33<>Apoyo!$B$10,$B33<>Apoyo!$B$2,$B33<>Apoyo!$B$6),B33,0)))} -> Ica | E33: Femenino | F33: =+IF(C33="Mujer",RANDBETWEEN(18,65),RANDBETWEEN(12,17)) -> 17 | G33: Completa | H33: =+IF($G33<>"Completa",IF($G33<>"Discapacidad",0,RANDBETWEEN(0,1)),RANDBETWEEN(0,1)) -> 1 | I33: =+IF($G33<>"Completa",IF($G33<>"Discapacidad",0,RANDBETWEEN(0,1)),RANDBETWEEN(0,1)) -> 0 | J33: =+IF(OR(H33=1,I33=1),RANDBETWEEN(0,1),0) -> 1 | K33: =IF(G33<>"Completa","n.a.",RAND()) -> 0.19728806 | L33: =+IFERROR(K33+0.05,"n.a.") -> 0.24728806
A34: =+RANDBETWEEN(Apoyo!$P$2,Apoyo!$P$3) -> 45948 | B34: {=+INDEX(Apoyo!$B$2:$B$10,RANDBETWEEN(1,9))} -> Ucayali | C34: NNA | D34: {=+IF(OR($B34=Apoyo!$B$2,$B34=Apoyo!$B$6),"Lima",IF($B34=Apoyo!$B$10,INDEX(Apoyo!$D$2:$D$19,RANDBETWEEN(1,18)),IF(OR($B34<>Apoyo!$B$10,$B34<>Apoyo!$B$2,$B34<>Apoyo!$B$6),B34,0)))} -> Ucayali | E34: Masculino | F34: =+IF(C34="Mujer",RANDBETWEEN(18,65),RANDBETWEEN(12,17)) -> 14 | G34: =+CHOOSE(RANDBETWEEN(1,5),Apoyo!$E$3,Apoyo!$E$4,Apoyo!$E$5,Apoyo!$E$6,Apoyo!$E$7) -> Aplazada | H34: =+IF($G34<>"Completa",IF($G34<>"Discapacidad",0,RANDBETWEEN(0,1)),RANDBETWEEN(0,1)) -> 0 | I34: =+IF($G34<>"Completa",IF($G34<>"Discapacidad",0,RANDBETWEEN(0,1)),RANDBETWEEN(0,1)) -> 0 | J34: =+IF(OR(H34=1,I34=1),RANDBETWEEN(0,1),0) -> 0 | K34: =IF(G34<>"Completa","n.a.",RAND()) -> n.a. | L34: =+IFERROR(K34+0.04,"n.a.") -> n.a.
A35: =+RANDBETWEEN(Apoyo!$P$2,Apoyo!$P$3) -> 45956 | B35: {=+INDEX(Apoyo!$B$2:$B$10,RANDBETWEEN(1,9))} -> Resto del Perú | C35: Mujer | D35: {=+IF(OR($B35=Apoyo!$B$2,$B35=Apoyo!$B$6),"Lima",IF($B35=Apoyo!$B$10,INDEX(Apoyo!$D$2:$D$19,RANDBETWEEN(1,18)),IF(OR($B35<>Apoyo!$B$10,$B35<>Apoyo!$B$2,$B35<>Apoyo!$B$6),B35,0)))} -> Ica | E35: =+IF(C35="Mujer","Femenino",2) -> Femenino | F35: =+IF(C35="Mujer",RANDBETWEEN(18,65),RANDBETWEEN(12,17)) -> 56 | G35: =+CHOOSE(RANDBETWEEN(1,5),Apoyo!$E$3,Apoyo!$E$4,Apoyo!$E$5,Apoyo!$E$6,Apoyo!$E$7) -> Ausente | H35: =+IF($G35<>"Completa",IF($G35<>"Discapacidad",0,RANDBETWEEN(0,1)),RANDBETWEEN(0,1)) -> 0 | I35: =+IF($G35<>"Completa",IF($G35<>"Discapacidad",0,RANDBETWEEN(0,1)),RANDBETWEEN(0,1)) -> 0 | J35: =+IF(OR(H35=1,I35=1),RANDBETWEEN(0,1),0) -> 0 | K35: =IF(G35<>"Completa","n.a.",RAND()) -> n.a. | L35: =+IFERROR(K35+0.05,"n.a.") -> n.a.
A36: =+RANDBETWEEN(Apoyo!$P$2,Apoyo!$P$3) -> 45957 | B36: {=+INDEX(Apoyo!$B$2:$B$10,RANDBETWEEN(1,9))} -> Lima Norte | C36: Mujer | D36: {=+IF(OR($B36=Apoyo!$B$2,$B36=Apoyo!$B$6),"Lima",IF($B36=Apoyo!$B$10,INDEX(Apoyo!$D$2:$D$19,RANDBETWEEN(1,18)),IF(OR($B36<>Apoyo!$B$10,$B36<>Apoyo!$B$2,$B36<>Apoyo!$B$6),B36,0)))} -> Lima | E36: =+IF(C36="Mujer","Femenino",2) -> Femenino | F36: =+IF(C36="Mujer",RANDBETWEEN(18,65),RANDBETWEEN(12,17)) -> 50 | G36: Completa | H36: =+IF($G36<>"Completa",IF($G36<>"Discapacidad",0,RANDBETWEEN(0,1)),RANDBETWEEN(0,1)) -> 1 | I36: =+IF($G36<>"Completa",IF($G36<>"Discapacidad",0,RANDBETWEEN(0,1)),RANDBETWEEN(0,1)) -> 0 | J36: =+IF(OR(H36=1,I36=1),RANDBETWEEN(0,1),0) -> 1 | K36: =IF(G36<>"Completa","n.a.",RAND()) -> 0.45470529 | L36: =+IFERROR(K36+0.03,"n.a.") -> 0.48470529
A37: =+RANDBETWEEN(Apoyo!$P$2,Apoyo!$P$3) -> 45955 | B37: {=+INDEX(Apoyo!$B$2:$B$10,RANDBETWEEN(1,9))} -> Ayacucho | C37: NNA | D37: {=+IF(OR($B37=Apoyo!$B$2,$B37=Apoyo!$B$6),"Lima",IF($B37=Apoyo!$B$10,INDEX(Apoyo!$D$2:$D$19,RANDBETWEEN(1,18)),IF(OR($B37<>Apoyo!$B$10,$B37<>Apoyo!$B$2,$B37<>Apoyo!$B$6),B37,0)))} -> Ayacucho | E37: Masculino | F37: =+IF(C37="Mujer",RANDBETWEEN(18,65),RANDBETWEEN(12,17)) -> 14 | G37: =+CHOOSE(RANDBETWEEN(1,5),Apoyo!$E$3,Apoyo!$E$4,Apoyo!$E$5,Apoyo!$E$6,Apoyo!$E$7) -> Otro | H37: =+IF($G37<>"Completa",IF($G37<>"Discapacidad",0,RANDBETWEEN(0,1)),RANDBETWEEN(0,1)) -> 0 | I37: =+IF($G37<>"Completa",IF($G37<>"Discapacidad",0,RANDBETWEEN(0,1)),RANDBETWEEN(0,1)) -> 0 | J37: =+IF(OR(H37=1,I37=1),RANDBETWEEN(0,1),0) -> 0 | K37: =IF(G37<>"Completa","n.a.",RAND()) -> n.a. | L37: =+IFERROR(K37+0.03,"n.a.") -> n.a.
A38: =+RANDBETWEEN(Apoyo!$P$2,Apoyo!$P$3) -> 45950 | B38: {=+INDEX(Apoyo!$B$2:$B$10,RANDBETWEEN(1,9))} -> Cajamarca | C38: NNA | D38: {=+IF(OR($B38=Apoyo!$B$2,$B38=Apoyo!$B$6),"Lima",IF($B38=Apoyo!$B$10,INDEX(Apoyo!$D$2:$D$19,RANDBETWEEN(1,18)),IF(OR($B38<>Apoyo!$B$10,$B38<>Apoyo!$B$2,$B38<>Apoyo!$B$6),B38,0)))} -> Cajamarca | E38: Femenino | F38: =+IF(C38="Mujer",RANDBETWEEN(18,65),RANDBETWEEN(12,17)) -> 15 | G38: Completa | H38: =+IF($G38<>"Completa",IF($G38<>"Discapacidad",0,RANDBETWEEN(0,1)),RANDBETWEEN(0,1)) -> 0 | I38: =+IF($G38<>"Completa",IF($G38<>"Discapacidad",0,RANDBETWEEN(0,1)),RANDBETWEEN(0,1)) -> 1 | J38: =+IF(OR(H38=1,I38=1),RANDBETWEEN(0,1),0) -> 0 | K38: =IF(G38<>"Completa","n.a.",RAND()) -> 0.98155085 | L38: =+IFERROR(K38+0.04,"n.a.") -> 1.0215509
A39: =+RANDBETWEEN(Apoyo!$P$2,Apoyo!$P$3) -> 45956 | B39: {=+INDEX(Apoyo!$B$2:$B$10,RANDBETWEEN(1,9))} -> Puente Piedra-Ventanilla | C39: Mujer | D39: {=+IF(OR($B39=Apoyo!$B$2,$B39=Apoyo!$B$6),"Lima",IF($B39=Apoyo!$B$10,INDEX(Apoyo!$D$2:$D$19,RANDBETWEEN(1,18)),IF(OR($B39<>Apoyo!$B$10,$B39<>Apoyo!$B$2,$B39<>Apoyo!$B$6),B39,0)))} -> Lima | E39: =+IF(C39="Mujer","Femenino",2) -> Femenino | F39: =+IF(C39="Mujer",RANDBETWEEN(18,65),RANDBETWEEN(12,17)) -> 23 | G39: =+CHOOSE(RANDBETWEEN(1,5),Apoyo!$E$3,Apoyo!$E$4,Apoyo!$E$5,Apoyo!$E$6,Apoyo!$E$7) -> Aplazada | H39: =+IF($G39<>"Completa",IF($G39<>"Discapacidad",0,RANDBETWEEN(0,1)),RANDBETWEEN(0,1)) -> 0 | I39: =+IF($G39<>"Completa",IF($G39<>"Discapacidad",0,RANDBETWEEN(0,1)),RANDBETWEEN(0,1)) -> 0 | J39: =+IF(OR(H39=1,I39=1),RANDBETWEEN(0,1),0) -> 0 | K39: =IF(G39<>"Completa","n.a.",RAND()) -> n.a. | L39: =+IFERROR(K39+0.05,"n.a.") -> n.a.
A40: =+RANDBETWEEN(Apoyo!$P$2,Apoyo!$P$3) -> 45951 | B40: {=+INDEX(Apoyo!$B$2:$B$10,RANDBETWEEN(1,9))} -> Puente Piedra-Ventanilla | C40: NNA | D40: {=+IF(OR($B40=Apoyo!$B$2,$B40=Apoyo!$B$6),"Lima",IF($B40=Apoyo!$B$10,INDEX(Apoyo!$D$2:$D$19,RANDBETWEEN(1,18)),IF(OR($B40<>Apoyo!$B$10,$B40<>Apoyo!$B$2,$B40<>Apoyo!$B$6),B40,0)))} -> Lima | E40: Masculino | F40: =+IF(C40="Mujer",RANDBETWEEN(18,65),RANDBETWEEN(12,17)) -> 17 | G40: =+CHOOSE(RANDBETWEEN(1,5),Apoyo!$E$3,Apoyo!$E$4,Apoyo!$E$5,Apoyo!$E$6,Apoyo!$E$7) -> Ausente | H40: =+IF($G40<>"Completa",IF($G40<>"Discapacidad",0,RANDBETWEEN(0,1)),RANDBETWEEN(0,1)) -> 0 | I40: =+IF($G40<>"Completa",IF($G40<>"Discapacidad",0,RANDBETWEEN(0,1)),RANDBETWEEN(0,1)) -> 0 | J40: =+IF(OR(H40=1,I40=1),RANDBETWEEN(0,1),0) -> 0 | K40: =IF(G40<>"Completa","n.a.",RAND()) -> n.a. | L40: =+IFERROR(K40+0.03,"n.a.") -> n.a.
...

Sheet Apoyo
B1: DDJJ | C1: DDJJ Tipo | D1: Departamento | E1: Resultado | F1: Contacto | G1: Entrevista | H1: Identificador | I1: Tipo de actor | J1: Sexo | K1: Asistencia | L1: Rol | M1: Hora | N1: Revisor | O1: Tipo | P1: Entrevistas | Q1: Resultado | R1: Duración
B2: Lima Norte | C2: Tratamiento | D2: Amazonas | E2: Completa | F2: No contactado | G2: Coordinada | I2: Funcionario/a | J2: Hombre | K2: Asistió | L2: Sobreviviente | M2: 0.375 | N2: 1 | O2: Violencia física | P2: 45945 | Q2: Completa | R2: 30
B3: Apurímac | C3: Tratamiento | D3: Áncash | E3: Ausente | F3: Contactado | G3: No coordinada | I3: Multilateral | J3: Mujer | K3: No asistió | L3: Líder sobreviviente | M3: 0.75 | N3: 8 | O3: Violencia sexual | P3: 45960 | Q3: Incompleta | R3: 50
B4: Huánuco | C4: Tratamiento | D4: Arequipa | E4: Aplazada | G4: Rechazada | I4: ONG | L4: Sobreviviente | O4: Feminicidio
B5: Ucayali | C5: Tratamiento | D5: Callao | E5: Rechazada | I5: Otros | O5: Violencia física
B6: Puente Piedra-Ventanilla | C6: Control | D6: Cusco | E6: Incompleta | O6: Violencia física
B7: Ayacucho | C7: Control | D7: Huancavelica | E7: Otro | O7: Violencia física
B8: Cajamarca | C8: Control | D8: Ica | O8: Violencia física
B9: Loreto | C9: Control | D9: Junín | O9: Violencia sexual
B10: Resto del Perú | C10: Resto del Perú | D10: La Libertad
D11: Lambayeque
D12: Madre de Dios
D13: Moquegua
D14: Pasco
D15: Piura
D16: Puno
D17: San Martín
D18: Tacna
D19: Tumbes

Sheet Hoja3
A1: Latitud | B1: Longitud
A2: 0.10651925 | B2: 0.12478933
A3: 0.11457889 | B3: 0.09137421
A4: 0.031403202 | B4: 0.041454544
A5: 0.10371877 | B5: 0.12688141
A6: 0.14905359 | B6: 0.047168073
A7: 0.047819045 | B7: 0.016255922
A8: 0.11355041 | B8: 0.10319095
A9: 0.1304005 | B9: 0.076384555
A10: 0.048252042 | B10: 0.01524317
A11: 0.10562484 | B11: 0.013947178
A12: 0.072415369 | B12: 0.1357993
A13: 0.02568457 | B13: 0.12111389
... A102: 0.091416917 | B102: 0.059064998
